Workbook

Sheet INVENTARIO
A1: Código interno | B1: Instrumento | C1: Marca | D1: Modelo | E1: N. Serial | F1: Ubicación | G1: Proceso | H1: Magnitud | I1: Criticidad | J1: Cap. Máxima instrumento | K1: Cap. Mínima instrumento | L1: Div. de escala | M1: Cap. Máxima proceso | N1: Cap. Mínima proceso | O1: Tolerancia del proceso | P1: Estado funcional | Q1: Intervalo calibración (meses) | R1: Calibración actual | S1: Alarma Calibración | T1: Proveedor calibración | U1: Intervalo verificación (meses) | V1: Última verificación | W1: Alarma Verificación | X1: Proveedor verificación | Y1: Intervalo mantenimiento (meses) | Z1: Último mantenimiento | AA1: Alarma Mantto | AB1: Proveedor mantenimiento | AC1: RESPONSABLE | AD1: Observaciones
A2: MJM-001 | B2: {=INDIRECT("'"&$B2&"'!$A$6")} -> MASA PATRÓN | C2: {=INDIRECT("'"&$B2&"'!$G$14")} -> TRUMAX | D2: {=INDIRECT("'"&$B2&"'!$G$15")} -> M1 | E2: {=INDIRECT("'"&$B2&"'!$G$16")} -> AG210714 | F2: LABORATORIO 1 | G2: OPERATIVO | H2: {=INDIRECT("'"&$B2&"'!$G$11")} -> MASA | I2: BAJA | J2: {=INDIRECT("'"&$B2&"'!$G$21")} -> 200 g | K2: {=INDIRECT("'"&$B2&"'!$G$22")} -> 200 g | L2: {=INDIRECT("'"&$B2&"'!$G$23")} -> N/A | N2: {=INDIRECT("'"&$B2&"'!$G$22")} -> 200 g | P2: {=IFERROR(LOOKUP(2,1/((INDIRECT("'"&$B2&"'!$G$29:$G$45"))<>""),(INDIRECT("'"&$B2&"'!$G$29:$G$45"))),"NO DISPONIBLE")} -> FUNCIONAL | Q2: N/A | R2: {=IF(IF(MAX((IFERROR((ROW(INDIRECT("'"&$B2&"'!$F$29:$F$45"))-ROW(INDIRECT("'"&$B2&"'!$F$29"))+1)/--(IF(INDIRECT("'"&$B2&"'!$F$29:$F$45")<>"",1,0)),0))-(IFERROR((ROW(INDIRECT("'"&$B2&"'!$F$29:$F$45"))-ROW(INDIRECT("'"&$B2&"'!$F$29"))+1)/--(FIND("VERIFICACIÓN: ", INDIRECT("'"&$B2&"'!$F$29:$F$45"))),0)))<>0,INDEX(INDIRECT("'"&$B2&"'!$A$29:$G$45"),MAX((IFERROR((ROW(INDIRECT("'"&$B2&"'!$F$29:$F$45"))-ROW(INDIRECT("'"&$B2&"'!$F$29"))+1)/--(IF(INDIRECT("'"&$B2&"'!$F$29:$F$45")<>"",1,0)),0))-(IFERROR((ROW(INDIRECT("'"&$B2&"'!$F$29:$F$45"))-ROW(INDIRECT("'"&$B2&"'!$F$29"))+1)/--(FIND("VERIFICACIÓN: ", INDIRECT("'"&$B2&"'!$F$29:$F$45"))),0))),1),0)>IF(MAX(IFERROR((_xlfn._xlws.FILTER((ROW(INDIRECT("'"&$B2&"'!$E$29:$E$45"))-ROW(INDIRECT("'"&$B2&"'!$E$29"))+1)/--(IF(INDIRECT("'"&$B2&"'!$E$29:$E$45")<>"",1,0)), NOT(ISNUMBER(MATCH((ROW(INDIRECT("'"&$B2&"'!$E$29:$E$45"))-ROW(INDIRECT("'"&$B2&"'!$E$29"))+1)/--(IF(INDIRECT("'"&$B2&"'!$E$29:$E$45")<>"",1,0)), (ROW(INDIRECT("'"&$B2&"'!$E$29:$E$45"))-ROW(INDIRECT("'"&$B2&"'!$E$29"))+1)/--(FIND("VERIFICACIÓN: ", INDIRECT("'"&$B2&"'!$E$29:$E$45"))), 0))))),0))<>0,INDEX(INDIRECT("'"&$B2&"'!$A$29:$G$45"),MAX((IFERROR((ROW(INDIRECT("'"&$B2&"'!$E$29:$E$45"))-ROW(INDIRECT("'"&$B2&"'!$E$29"))+1)/--(IF(INDIRECT("'"&$B2&"'!$E$29:$E$45")<>"",1,0)),0))-(IFERROR((ROW(INDIRECT("'"&$B2&"'!$E$29:$E$45"))-ROW(INDIRECT("'"&$B2&"'!$E$29"))+1)/--(FIND("VERIFICACIÓN: ", INDIRECT("'"&$B2&"'!$E$29:$E$45"))),0))),1),0),IF(MAX((IFERROR((ROW(INDIRECT("'"&$B2&"'!$F$29:$F$45"))-ROW(INDIRECT("'"&$B2&"'!$F$29"))+1)/--(IF(INDIRECT("'"&$B2&"'!$F$29:$F$45")<>"",1,0)),0))-(IFERROR((ROW(INDIRECT("'"&$B2&"'!$F$29:$F$45"))-ROW(INDIRECT("'"&$B2&"'!$F$29"))+1)/--(FIND("VERIFICACIÓN: ", INDIRECT("'"&$B2&"'!$F$29:$F$45"))),0)))<>0,INDEX(INDIRECT("'"&$B2&"'!$A$29:$G$45"),MAX((IFERROR((ROW(INDIRECT("'"&$B2&"'!$F$29:$F$45"))-ROW(INDIRECT("'"&$B2&"'!$F$29"))+1)/--(IF(INDIRECT("'"&$B2&"'!$F$29:$F$45")<>"",1,0)),0))-(IFERROR((ROW(INDIRECT("'"&$B2&"'!$F$29:$F$45"))-ROW(INDIRECT("'"&$B2&"'!$F$29"))+1)/--(FIND("VERIFICACIÓN: ", INDIRECT("'"&$B2&"'!$F$29:$F$45"))),0))),1),0),IF(MAX(IFERROR((_xlfn._xlws.FILTER((ROW(INDIRECT("'"&$B2&"'!$E$29:$E$45"))-ROW(INDIRECT("'"&$B2&"'!$E$29"))+1)/--(IF(INDIRECT("'"&$B2&"'!$E$29:$E$45")<>"",1,0)), NOT(ISNUMBER(MATCH((ROW(INDIRECT("'"&$B2&"'!$E$29:$E$45"))-ROW(INDIRECT("'"&$B2&"'!$E$29"))+1)/--(IF(INDIRECT("'"&$B2&"'!$E$29:$E$45")<>"",1,0)), (ROW(INDIRECT("'"&$B2&"'!$E$29:$E$45"))-ROW(INDIRECT("'"&$B2&"'!$E$29"))+1)/--(FIND("VERIFICACIÓN: ", INDIRECT("'"&$B2&"'!$E$29:$E$45"))), 0))))),0))<>0,INDEX(INDIRECT("'"&$B2&"'!$A$29:$G$45"),MAX((IFERROR((ROW(INDIRECT("'"&$B2&"'!$E$29:$E$45"))-ROW(INDIRECT("'"&$B2&"'!$E$29"))+1)/--(IF(INDIRECT("'"&$B2&"'!$E$29:$E$45")<>"",1,0)),0))-(IFERROR((ROW(INDIRECT("'"&$B2&"'!$E$29:$E$45"))-ROW(INDIRECT("'"&$B2&"'!$E$29"))+1)/--(FIND("VERIFICACIÓN: ", INDIRECT("'"&$B2&"'!$E$29:$E$45"))),0))),1),0))} -> 0 | S2: No aplica | T2: {=IF(IF(MAX((IFERROR((ROW(INDIRECT("'"&$B2&"'!$F$29:$F$45"))-ROW(INDIRECT("'"&$B2&"'!$F$29"))+1)/--(IF(INDIRECT("'"&$B2&"'!$F$29:$F$45")<>"",1,0)),0))-(IFERROR((ROW(INDIRECT("'"&$B2&"'!$F$29:$F$45"))-ROW(INDIRECT("'"&$B2&"'!$F$29"))+1)/--(FIND("VERIFICACIÓN: ", INDIRECT("'"&$B2&"'!$F$29:$F$45"))),0)))<>0,INDEX(INDIRECT("'"&$B2&"'!$A$29:$G$45"),MAX((IFERROR((ROW(INDIRECT("'"&$B2&"'!$F$29:$F$45"))-ROW(INDIRECT("'"&$B2&"'!$F$29"))+1)/--(IF(INDIRECT("'"&$B2&"'!$F$29:$F$45")<>"",1,0)),0))-(IFERROR((ROW(INDIRECT("'"&$B2&"'!$F$29:$F$45"))-ROW(INDIRECT("'"&$B2&"'!$F$29"))+1)/--(FIND("VERIFICACIÓN: ", INDIRECT("'"&$B2&"'!$F$29:$F$45"))),0))),1),0)>IF(MAX(IFERROR((_xlfn._xlws.FILTER((ROW(INDIRECT("'"&$B2&"'!$E$29:$E$45"))-ROW(INDIRECT("'"&$B2&"'!$E$29"))+1)/--(IF(INDIRECT("'"&$B2&"'!$E$29:$E$45")<>"",1,0)), NOT(ISNUMBER(MATCH((ROW(INDIRECT("'"&$B2&"'!$E$29:$E$45"))-ROW(INDIRECT("'"&$B2&"'!$E$29"))+1)/--(IF(INDIRECT("'"&$B2&"'!$E$29:$E$45")<>"",1,0)), (ROW(INDIRECT("'"&$B2&"'!$E$29:$E$45"))-ROW(INDIRECT("'"&$B2&"'!$E$29"))+1)/--(FIND("VERIFICACIÓN: ", INDIRECT("'"&$B2&"'!$E$29:$E$45"))), 0))))),0))<>0,INDEX(INDIRECT("'"&$B2&"'!$A$29:$G$45"),MAX((IFERROR((ROW(INDIRECT("'"&$B2&"'!$E$29:$E$45"))-ROW(INDIRECT("'"&$B2&"'!$E$29"))+1)/--(IF(INDIRECT("'"&$B2&"'!$E$29:$E$45")<>"",1,0)),0))-(IFERROR((ROW(INDIRECT("'"&$B2&"'!$E$29:$E$45"))-ROW(INDIRECT("'"&$B2&"'!$E$29"))+1)/--(FIND("VERIFICACIÓN: ", INDIRECT("'"&$B2&"'!$E$29:$E$45"))),0))),1),0),IF(MAX((IFERROR((ROW(INDIRECT("'"&$B2&"'!$F$29:$F$45"))-ROW(INDIRECT("'"&$B2&"'!$F$29"))+1)/--(IF(INDIRECT("'"&$B2&"'!$F$29:$F$45")<>"",1,0)),0))-(IFERROR((ROW(INDIRECT("'"&$B2&"'!$F$29:$F$45"))-ROW(INDIRECT("'"&$B2&"'!$F$29"))+1)/--(FIND("VERIFICACIÓN: ", INDIRECT("'"&$B2&"'!$F$29:$F$45"))),0)))<>0,INDEX(INDIRECT("'"&$B2&"'!$A$29:$G$45"),MAX((IFERROR((ROW(INDIRECT("'"&$B2&"'!$F$29:$F$45"))-ROW(INDIRECT("'"&$B2&"'!$F$29"))+1)/--(IF(INDIRECT("'"&$B2&"'!$F$29:$F$45")<>"",1,0)),0))-(IFERROR((ROW(INDIRECT("'"&$B2&"'!$F$29:$F$45"))-ROW(INDIRECT("'"&$B2&"'!$F$29"))+1)/--(FIND("VERIFICACIÓN: ", INDIRECT("'"&$B2&"'!$F$29:$F$45"))),0))),6),"NO DISPONIBLE"),IF(MAX(IFERROR((_xlfn._xlws.FILTER((ROW(INDIRECT("'"&$B2&"'!$E$29:$E$45"))-ROW(INDIRECT("'"&$B2&"'!$E$29"))+1)/--(IF(INDIRECT("'"&$B2&"'!$E$29:$E$45")<>"",1,0)), NOT(ISNUMBER(MATCH((ROW(INDIRECT("'"&$B2&"'!$E$29:$E$45"))-ROW(INDIRECT("'"&$B2&"'!$E$29"))+1)/--(IF(INDIRECT("'"&$B2&"'!$E$29:$E$45")<>"",1,0)), (ROW(INDIRECT("'"&$B2&"'!$E$29:$E$45"))-ROW(INDIRECT("'"&$B2&"'!$E$29"))+1)/--(FIND("VERIFICACIÓN: ", INDIRECT("'"&$B2&"'!$E$29:$E$45"))), 0))))),0))<>0,INDEX(INDIRECT("'"&$B2&"'!$A$29:$G$45"),MAX((IFERROR((ROW(INDIRECT("'"&$B2&"'!$E$29:$E$45"))-ROW(INDIRECT("'"&$B2&"'!$E$29"))+1)/--(IF(INDIRECT("'"&$B2&"'!$E$29:$E$45")<>"",1,0)),0))-(IFERROR((ROW(INDIRECT("'"&$B2&"'!$E$29:$E$45"))-ROW(INDIRECT("'"&$B2&"'!$E$29"))+1)/--(FIND("VERIFICACIÓN: ", INDIRECT("'"&$B2&"'!$E$29:$E$45"))),0))),5),"NO DISPONIBLE"))} -> NO DISPONIBLE | U2: N/A | V2: {=IF((IFERROR(VLOOKUP(IFERROR(LOOKUP(2,1/((INDIRECT("'"&$B2&"'!$F$29:$F$45"))<>""),(INDIRECT("'"&$B2&"'!$F$29:$F$45"))),"NO DISPONIBLE"),CHOOSE({1,2},(INDIRECT("'"&$B2&"'!$F$29:$F$45")),(INDIRECT("'"&$B2&"'!$A$29:$A$45"))),2,0),0))>(IFERROR(VLOOKUP(IFERROR(LOOKUP(2,1/((INDIRECT("'"&$B2&"'!$E$29:$E$45"))<>""),(INDIRECT("'"&$B2&"'!$E$29:$E$45"))),"NO DISPONIBLE"),CHOOSE({1,2},(INDIRECT("'"&$B2&"'!$E$29:$E$45")),(INDIRECT("'"&$B2&"'!$A$29:$A$45"))),2,0),0)),(IFERROR(VLOOKUP(IFERROR(LOOKUP(2,1/((INDIRECT("'"&$B2&"'!$F$29:$F$45"))<>""),(INDIRECT("'"&$B2&"'!$F$29:$F$45"))),"NO DISPONIBLE"),CHOOSE({1,2},(INDIRECT("'"&$B2&"'!$F$29:$F$45")),(INDIRECT("'"&$B2&"'!$A$29:$A$45"))),2,0),0)),(IFERROR(VLOOKUP(IFERROR(LOOKUP(2,1/((INDIRECT("'"&$B2&"'!$E$29:$E$45"))<>""),(INDIRECT("'"&$B2&"'!$E$29:$E$45"))),"NO DISPONIBLE"),CHOOSE({1,2},(INDIRECT("'"&$B2&"'!$E$29:$E$45")),(INDIRECT("'"&$B2&"'!$A$29:$A$45"))),2,0),0)))} -> 0 | W2: No aplica | X2: {=IF((IFERROR(VLOOKUP(IFERROR(LOOKUP(2,1/((INDIRECT("'"&$B2&"'!$E$29:$E$45"))<>""),(INDIRECT("'"&$B2&"'!$E$29:$E$45"))),"NO DISPONIBLE"),CHOOSE({1,2},(INDIRECT("'"&$B2&"'!$E$29:$E$45")),(INDIRECT("'"&$B2&"'!$A$29:$A$45"))),2,0),0))>(IFERROR(VLOOKUP(IFERROR(LOOKUP(2,1/((INDIRECT("'"&$B2&"'!$F$29:$F$45"))<>""),(INDIRECT("'"&$B2&"'!$F$29:$F$45"))),"NO DISPONIBLE"),CHOOSE({1,2},(INDIRECT("'"&$B2&"'!$F$29:$F$45")),(INDIRECT("'"&$B2&"'!$A$29:$A$45"))),2,0),0)),IFERROR(LOOKUP(2,1/((INDIRECT("'"&$B2&"'!$E$29:$E$45"))<>""),(INDIRECT("'"&$B2&"'!$E$29:$E$45"))),"NO DISPONIBLE"),IFERROR(LOOKUP(2,1/((INDIRECT("'"&$B2&"'!$F$29:$F$45"))<>""),(INDIRECT("'"&$B2&"'!$F$29:$F$45"))),"NO DISPONIBLE"))} -> NO DISPONIBLE | Y2: N/A | Z2: {=IF((IFERROR(VLOOKUP(IFERROR(LOOKUP(2,1/((INDIRECT("'"&$B2&"'!$D$29:$D$45"))<>""),(INDIRECT("'"&$B2&"'!$D$29:$D$45"))),"NO DISPONIBLE"),CHOOSE({1,2},(INDIRECT("'"&$B2&"'!$D$29:$D$45")),(INDIRECT("'"&$B2&"'!$A$29:$A$45"))),2,0),0))>(IFERROR(VLOOKUP(IFERROR(LOOKUP(2,1/((INDIRECT("'"&$B2&"'!$C$29:$C$45"))<>""),(INDIRECT("'"&$B2&"'!$C$29:$C$45"))),"NO DISPONIBLE"),CHOOSE({1,2},(INDIRECT("'"&$B2&"'!$C$29:$C$45")),(INDIRECT("'"&$B2&"'!$A$29:$A$45"))),2,0),0)),(IFERROR(VLOOKUP(IFERROR(LOOKUP(2,1/((INDIRECT("'"&$B2&"'!$D$29:$D$45"))<>""),(INDIRECT("'"&$B2&"'!$D$29:$D$45"))),"NO DISPONIBLE"),CHOOSE({1,2},(INDIRECT("'"&$B2&"'!$D$29:$D$45")),(INDIRECT("'"&$B2&"'!$A$29:$A$45"))),2,0),0)),(IFERROR(VLOOKUP(IFERROR(LOOKUP(2,1/((INDIRECT("'"&$B2&"'!$C$29:$C$45"))<>""),(INDIRECT("'"&$B2&"'!$C$29:$C$45"))),"NO DISPONIBLE"),CHOOSE({1,2},(INDIRECT("'"&$B2&"'!$C$29:$C$45")),(INDIRECT("'"&$B2&"'!$A$29:$A$45"))),2,0),0)))} -> 0 | AA2: No aplica | AB2: {=IF((IFERROR(VLOOKUP(IFERROR(LOOKUP(2,1/((INDIRECT("'"&$B2&"'!$C$29:$C$45"))<>""),(INDIRECT("'"&$B2&"'!$C$29:$C$45"))),"NO DISPONIBLE"),CHOOSE({1,2},(INDIRECT("'"&$B2&"'!$C$29:$C$45")),(INDIRECT("'"&$B2&"'!$A$29:$A$45"))),2,0),0))>(IFERROR(VLOOKUP(IFERROR(LOOKUP(2,1/((INDIRECT("'"&$B2&"'!$D$29:$D$45"))<>""),(INDIRECT("'"&$B2&"'!$D$29:$D$45"))),"NO DISPONIBLE"),CHOOSE({1,2},(INDIRECT("'"&$B2&"'!$D$29:$D$45")),(INDIRECT("'"&$B2&"'!$A$29:$A$45"))),2,0),0)),IFERROR(LOOKUP(2,1/((INDIRECT("'"&$B2&"'!$C$29:$C$45"))<>""),(INDIRECT("'"&$B2&"'!$C$29:$C$45"))),"NO DISPONIBLE"),IFERROR(LOOKUP(2,1/((INDIRECT("'"&$B2&"'!$D$29:$D$45"))<>""),(INDIRECT("'"&$B2&"'!$D$29:$D$45"))),"NO DISPONIBLE"))} -> NO DISPONIBLE | AC2: ASEGURAMIENTO
A3: MJM-002 | B3: {=INDIRECT("'"&$B3&"'!$A$6")} -> MASA PATRÓN | C3: {=INDIRECT("'"&$B3&"'!$G$14")} -> TRUMAX | D3: {=INDIRECT("'"&$B3&"'!$G$15")} -> M1 | E3: {=INDIRECT("'"&$B3&"'!$G$16")} -> AG210688 | F3: LABORATORIO 1 | G3: OPERATIVO | H3: {=INDIRECT("'"&$B3&"'!$G$11")} -> MASA | I3: BAJA | J3: {=INDIRECT("'"&$B3&"'!$G$21")} -> 100 g | K3: {=INDIRECT("'"&$B3&"'!$G$22")} -> 100 g | L3: {=INDIRECT("'"&$B3&"'!$G$23")} -> N/A | N3: {=INDIRECT("'"&$B3&"'!$G$22")} -> 100 g | P3: {=IFERROR(LOOKUP(2,1/((INDIRECT("'"&$B3&"'!$G$29:$G$45"))<>""),(INDIRECT("'"&$B3&"'!$G$29:$G$45"))),"NO DISPONIBLE")} -> FUNCIONAL | Q3: N/A | R3: {=IF(IF(MAX((IFERROR((ROW(INDIRECT("'"&$B3&"'!$F$29:$F$45"))-ROW(INDIRECT("'"&$B3&"'!$F$29"))+1)/--(IF(INDIRECT("'"&$B3&"'!$F$29:$F$45")<>"",1,0)),0))-(IFERROR((ROW(INDIRECT("'"&$B3&"'!$F$29:$F$45"))-ROW(INDIRECT("'"&$B3&"'!$F$29"))+1)/--(FIND("VERIFICACIÓN: ", INDIRECT("'"&$B3&"'!$F$29:$F$45"))),0)))<>0,INDEX(INDIRECT("'"&$B3&"'!$A$29:$G$45"),MAX((IFERROR((ROW(INDIRECT("'"&$B3&"'!$F$29:$F$45"))-ROW(INDIRECT("'"&$B3&"'!$F$29"))+1)/--(IF(INDIRECT("'"&$B3&"'!$F$29:$F$45")<>"",1,0)),0))-(IFERROR((ROW(INDIRECT("'"&$B3&"'!$F$29:$F$45"))-ROW(INDIRECT("'"&$B3&"'!$F$29"))+1)/--(FIND("VERIFICACIÓN: ", INDIRECT("'"&$B3&"'!$F$29:$F$45"))),0))),1),0)>IF(MAX(IFERROR((_xlfn._xlws.FILTER((ROW(INDIRECT("'"&$B3&"'!$E$29:$E$45"))-ROW(INDIRECT("'"&$B3&"'!$E$29"))+1)/--(IF(INDIRECT("'"&$B3&"'!$E$29:$E$45")<>"",1,0)), NOT(ISNUMBER(MATCH((ROW(INDIRECT("'"&$B3&"'!$E$29:$E$45"))-ROW(INDIRECT("'"&$B3&"'!$E$29"))+1)/--(IF(INDIRECT("'"&$B3&"'!$E$29:$E$45")<>"",1,0)), (ROW(INDIRECT("'"&$B3&"'!$E$29:$E$45"))-ROW(INDIRECT("'"&$B3&"'!$E$29"))+1)/--(FIND("VERIFICACIÓN: ", INDIRECT("'"&$B3&"'!$E$29:$E$45"))), 0))))),0))<>0,INDEX(INDIRECT("'"&$B3&"'!$A$29:$G$45"),MAX((IFERROR((ROW(INDIRECT("'"&$B3&"'!$E$29:$E$45"))-ROW(INDIRECT("'"&$B3&"'!$E$29"))+1)/--(IF(INDIRECT("'"&$B3&"'!$E$29:$E$45")<>"",1,0)),0))-(IFERROR((ROW(INDIRECT("'"&$B3&"'!$E$29:$E$45"))-ROW(INDIRECT("'"&$B3&"'!$E$29"))+1)/--(FIND("VERIFICACIÓN: ", INDIRECT("'"&$B3&"'!$E$29:$E$45"))),0))),1),0),IF(MAX((IFERROR((ROW(INDIRECT("'"&$B3&"'!$F$29:$F$45"))-ROW(INDIRECT("'"&$B3&"'!$F$29"))+1)/--(IF(INDIRECT("'"&$B3&"'!$F$29:$F$45")<>"",1,0)),0))-(IFERROR((ROW(INDIRECT("'"&$B3&"'!$F$29:$F$45"))-ROW(INDIRECT("'"&$B3&"'!$F$29"))+1)/--(FIND("VERIFICACIÓN: ", INDIRECT("'"&$B3&"'!$F$29:$F$45"))),0)))<>0,INDEX(INDIRECT("'"&$B3&"'!$A$29:$G$45"),MAX((IFERROR((ROW(INDIRECT("'"&$B3&"'!$F$29:$F$45"))-ROW(INDIRECT("'"&$B3&"'!$F$29"))+1)/--(IF(INDIRECT("'"&$B3&"'!$F$29:$F$45")<>"",1,0)),0))-(IFERROR((ROW(INDIRECT("'"&$B3&"'!$F$29:$F$45"))-ROW(INDIRECT("'"&$B3&"'!$F$29"))+1)/--(FIND("VERIFICACIÓN: ", INDIRECT("'"&$B3&"'!$F$29:$F$45"))),0))),1),0),IF(MAX(IFERROR((_xlfn._xlws.FILTER((ROW(INDIRECT("'"&$B3&"'!$E$29:$E$45"))-ROW(INDIRECT("'"&$B3&"'!$E$29"))+1)/--(IF(INDIRECT("'"&$B3&"'!$E$29:$E$45")<>"",1,0)), NOT(ISNUMBER(MATCH((ROW(INDIRECT("'"&$B3&"'!$E$29:$E$45"))-ROW(INDIRECT("'"&$B3&"'!$E$29"))+1)/--(IF(INDIRECT("'"&$B3&"'!$E$29:$E$45")<>"",1,0)), (ROW(INDIRECT("'"&$B3&"'!$E$29:$E$45"))-ROW(INDIRECT("'"&$B3&"'!$E$29"))+1)/--(FIND("VERIFICACIÓN: ", INDIRECT("'"&$B3&"'!$E$29:$E$45"))), 0))))),0))<>0,INDEX(INDIRECT("'"&$B3&"'!$A$29:$G$45"),MAX((IFERROR((ROW(INDIRECT("'"&$B3&"'!$E$29:$E$45"))-ROW(INDIRECT("'"&$B3&"'!$E$29"))+1)/--(IF(INDIRECT("'"&$B3&"'!$E$29:$E$45")<>"",1,0)),0))-(IFERROR((ROW(INDIRECT("'"&$B3&"'!$E$29:$E$45"))-ROW(INDIRECT("'"&$B3&"'!$E$29"))+1)/--(FIND("VERIFICACIÓN: ", INDIRECT("'"&$B3&"'!$E$29:$E$45"))),0))),1),0))} -> 0 | S3: No aplica | T3: {=IF(IF(MAX((IFERROR((ROW(INDIRECT("'"&$B3&"'!$F$29:$F$45"))-ROW(INDIRECT("'"&$B3&"'!$F$29"))+1)/--(IF(INDIRECT("'"&$B3&"'!$F$29:$F$45")<>"",1,0)),0))-(IFERROR((ROW(INDIRECT("'"&$B3&"'!$F$29:$F$45"))-ROW(INDIRECT("'"&$B3&"'!$F$29"))+1)/--(FIND("VERIFICACIÓN: ", INDIRECT("'"&$B3&"'!$F$29:$F$45"))),0)))<>0,INDEX(INDIRECT("'"&$B3&"'!$A$29:$G$45"),MAX((IFERROR((ROW(INDIRECT("'"&$B3&"'!$F$29:$F$45"))-ROW(INDIRECT("'"&$B3&"'!$F$29"))+1)/--(IF(INDIRECT("'"&$B3&"'!$F$29:$F$45")<>"",1,0)),0))-(IFERROR((ROW(INDIRECT("'"&$B3&"'!$F$29:$F$45"))-ROW(INDIRECT("'"&$B3&"'!$F$29"))+1)/--(FIND("VERIFICACIÓN: ", INDIRECT("'"&$B3&"'!$F$29:$F$45"))),0))),1),0)>IF(MAX(IFERROR((_xlfn._xlws.FILTER((ROW(INDIRECT("'"&$B3&"'!$E$29:$E$45"))-ROW(INDIRECT("'"&$B3&"'!$E$29"))+1)/--(IF(INDIRECT("'"&$B3&"'!$E$29:$E$45")<>"",1,0)), NOT(ISNUMBER(MATCH((ROW(INDIRECT("'"&$B3&"'!$E$29:$E$45"))-ROW(INDIRECT("'"&$B3&"'!$E$29"))+1)/--(IF(INDIRECT("'"&$B3&"'!$E$29:$E$45")<>"",1,0)), (ROW(INDIRECT("'"&$B3&"'!$E$29:$E$45"))-ROW(INDIRECT("'"&$B3&"'!$E$29"))+1)/--(FIND("VERIFICACIÓN: ", INDIRECT("'"&$B3&"'!$E$29:$E$45"))), 0))))),0))<>0,INDEX(INDIRECT("'"&$B3&"'!$A$29:$G$45"),MAX((IFERROR((ROW(INDIRECT("'"&$B3&"'!$E$29:$E$45"))-ROW(INDIRECT("'"&$B3&"'!$E$29"))+1)/--(IF(INDIRECT("'"&$B3&"'!$E$29:$E$45")<>"",1,0)),0))-(IFERROR((ROW(INDIRECT("'"&$B3&"'!$E$29:$E$45"))-ROW(INDIRECT("'"&$B3&"'!$E$29"))+1)/--(FIND("VERIFICACIÓN: ", INDIRECT("'"&$B3&"'!$E$29:$E$45"))),0))),1),0),IF(MAX((IFERROR((ROW(INDIRECT("'"&$B3&"'!$F$29:$F$45"))-ROW(INDIRECT("'"&$B3&"'!$F$29"))+1)/--(IF(INDIRECT("'"&$B3&"'!$F$29:$F$45")<>"",1,0)),0))-(IFERROR((ROW(INDIRECT("'"&$B3&"'!$F$29:$F$45"))-ROW(INDIRECT("'"&$B3&"'!$F$29"))+1)/--(FIND("VERIFICACIÓN: ", INDIRECT("'"&$B3&"'!$F$29:$F$45"))),0)))<>0,INDEX(INDIRECT("'"&$B3&"'!$A$29:$G$45"),MAX((IFERROR((ROW(INDIRECT("'"&$B3&"'!$F$29:$F$45"))-ROW(INDIRECT("'"&$B3&"'!$F$29"))+1)/--(IF(INDIRECT("'"&$B3&"'!$F$29:$F$45")<>"",1,0)),0))-(IFERROR((ROW(INDIRECT("'"&$B3&"'!$F$29:$F$45"))-ROW(INDIRECT("'"&$B3&"'!$F$29"))+1)/--(FIND("VERIFICACIÓN: ", INDIRECT("'"&$B3&"'!$F$29:$F$45"))),0))),6),"NO DISPONIBLE"),IF(MAX(IFERROR((_xlfn._xlws.FILTER((ROW(INDIRECT("'"&$B3&"'!$E$29:$E$45"))-ROW(INDIRECT("'"&$B3&"'!$E$29"))+1)/--(IF(INDIRECT("'"&$B3&"'!$E$29:$E$45")<>"",1,0)), NOT(ISNUMBER(MATCH((ROW(INDIRECT("'"&$B3&"'!$E$29:$E$45"))-ROW(INDIRECT("'"&$B3&"'!$E$29"))+1)/--(IF(INDIRECT("'"&$B3&"'!$E$29:$E$45")<>"",1,0)), (ROW(INDIRECT("'"&$B3&"'!$E$29:$E$45"))-ROW(INDIRECT("'"&$B3&"'!$E$29"))+1)/--(FIND("VERIFICACIÓN: ", INDIRECT("'"&$B3&"'!$E$29:$E$45"))), 0))))),0))<>0,INDEX(INDIRECT("'"&$B3&"'!$A$29:$G$45"),MAX((IFERROR((ROW(INDIRECT("'"&$B3&"'!$E$29:$E$45"))-ROW(INDIRECT("'"&$B3&"'!$E$29"))+1)/--(IF(INDIRECT("'"&$B3&"'!$E$29:$E$45")<>"",1,0)),0))-(IFERROR((ROW(INDIRECT("'"&$B3&"'!$E$29:$E$45"))-ROW(INDIRECT("'"&$B3&"'!$E$29"))+1)/--(FIND("VERIFICACIÓN: ", INDIRECT("'"&$B3&"'!$E$29:$E$45"))),0))),5),"NO DISPONIBLE"))} -> NO DISPONIBLE | U3: N/A | V3: {=IF((IFERROR(VLOOKUP(IFERROR(LOOKUP(2,1/((INDIRECT("'"&$B3&"'!$F$29:$F$45"))<>""),(INDIRECT("'"&$B3&"'!$F$29:$F$45"))),"NO DISPONIBLE"),CHOOSE({1,2},(INDIRECT("'"&$B3&"'!$F$29:$F$45")),(INDIRECT("'"&$B3&"'!$A$29:$A$45"))),2,0),0))>(IFERROR(VLOOKUP(IFERROR(LOOKUP(2,1/((INDIRECT("'"&$B3&"'!$E$29:$E$45"))<>""),(INDIRECT("'"&$B3&"'!$E$29:$E$45"))),"NO DISPONIBLE"),CHOOSE({1,2},(INDIRECT("'"&$B3&"'!$E$29:$E$45")),(INDIRECT("'"&$B3&"'!$A$29:$A$45"))),2,0),0)),(IFERROR(VLOOKUP(IFERROR(LOOKUP(2,1/((INDIRECT("'"&$B3&"'!$F$29:$F$45"))<>""),(INDIRECT("'"&$B3&"'!$F$29:$F$45"))),"NO DISPONIBLE"),CHOOSE({1,2},(INDIRECT("'"&$B3&"'!$F$29:$F$45")),(INDIRECT("'"&$B3&"'!$A$29:$A$45"))),2,0),0)),(IFERROR(VLOOKUP(IFERROR(LOOKUP(2,1/((INDIRECT("'"&$B3&"'!$E$29:$E$45"))<>""),(INDIRECT("'"&$B3&"'!$E$29:$E$45"))),"NO DISPONIBLE"),CHOOSE({1,2},(INDIRECT("'"&$B3&"'!$E$29:$E$45")),(INDIRECT("'"&$B3&"'!$A$29:$A$45"))),2,0),0)))} -> 0 | W3: No aplica | X3: {=IF((IFERROR(VLOOKUP(IFERROR(LOOKUP(2,1/((INDIRECT("'"&$B3&"'!$E$29:$E$45"))<>""),(INDIRECT("'"&$B3&"'!$E$29:$E$45"))),"NO DISPONIBLE"),CHOOSE({1,2},(INDIRECT("'"&$B3&"'!$E$29:$E$45")),(INDIRECT("'"&$B3&"'!$A$29:$A$45"))),2,0),0))>(IFERROR(VLOOKUP(IFERROR(LOOKUP(2,1/((INDIRECT("'"&$B3&"'!$F$29:$F$45"))<>""),(INDIRECT("'"&$B3&"'!$F$29:$F$45"))),"NO DISPONIBLE"),CHOOSE({1,2},(INDIRECT("'"&$B3&"'!$F$29:$F$45")),(INDIRECT("'"&$B3&"'!$A$29:$A$45"))),2,0),0)),IFERROR(LOOKUP(2,1/((INDIRECT("'"&$B3&"'!$E$29:$E$45"))<>""),(INDIRECT("'"&$B3&"'!$E$29:$E$45"))),"NO DISPONIBLE"),IFERROR(LOOKUP(2,1/((INDIRECT("'"&$B3&"'!$F$29:$F$45"))<>""),(INDIRECT("'"&$B3&"'!$F$29:$F$45"))),"NO DISPONIBLE"))} -> NO DISPONIBLE | Y3: N/A | Z3: {=IF((IFERROR(VLOOKUP(IFERROR(LOOKUP(2,1/((INDIRECT("'"&$B3&"'!$D$29:$D$45"))<>""),(INDIRECT("'"&$B3&"'!$D$29:$D$45"))),"NO DISPONIBLE"),CHOOSE({1,2},(INDIRECT("'"&$B3&"'!$D$29:$D$45")),(INDIRECT("'"&$B3&"'!$A$29:$A$45"))),2,0),0))>(IFERROR(VLOOKUP(IFERROR(LOOKUP(2,1/((INDIRECT("'"&$B3&"'!$C$29:$C$45"))<>""),(INDIRECT("'"&$B3&"'!$C$29:$C$45"))),"NO DISPONIBLE"),CHOOSE({1,2},(INDIRECT("'"&$B3&"'!$C$29:$C$45")),(INDIRECT("'"&$B3&"'!$A$29:$A$45"))),2,0),0)),(IFERROR(VLOOKUP(IFERROR(LOOKUP(2,1/((INDIRECT("'"&$B3&"'!$D$29:$D$45"))<>""),(INDIRECT("'"&$B3&"'!$D$29:$D$45"))),"NO DISPONIBLE"),CHOOSE({1,2},(INDIRECT("'"&$B3&"'!$D$29:$D$45")),(INDIRECT("'"&$B3&"'!$A$29:$A$45"))),2,0),0)),(IFERROR(VLOOKUP(IFERROR(LOOKUP(2,1/((INDIRECT("'"&$B3&"'!$C$29:$C$45"))<>""),(INDIRECT("'"&$B3&"'!$C$29:$C$45"))),"NO DISPONIBLE"),CHOOSE({1,2},(INDIRECT("'"&$B3&"'!$C$29:$C$45")),(INDIRECT("'"&$B3&"'!$A$29:$A$45"))),2,0),0)))} -> 0 | AA3: No aplica | AB3: {=IF((IFERROR(VLOOKUP(IFERROR(LOOKUP(2,1/((INDIRECT("'"&$B3&"'!$C$29:$C$45"))<>""),(INDIRECT("'"&$B3&"'!$C$29:$C$45"))),"NO DISPONIBLE"),CHOOSE({1,2},(INDIRECT("'"&$B3&"'!$C$29:$C$45")),(INDIRECT("'"&$B3&"'!$A$29:$A$45"))),2,0),0))>(IFERROR(VLOOKUP(IFERROR(LOOKUP(2,1/((INDIRECT("'"&$B3&"'!$D$29:$D$45"))<>""),(INDIRECT("'"&$B3&"'!$D$29:$D$45"))),"NO DISPONIBLE"),CHOOSE({1,2},(INDIRECT("'"&$B3&"'!$D$29:$D$45")),(INDIRECT("'"&$B3&"'!$A$29:$A$45"))),2,0),0)),IFERROR(LOOKUP(2,1/((INDIRECT("'"&$B3&"'!$C$29:$C$45"))<>""),(INDIRECT("'"&$B3&"'!$C$29:$C$45"))),"NO DISPONIBLE"),IFERROR(LOOKUP(2,1/((INDIRECT("'"&$B3&"'!$D$29:$D$45"))<>""),(INDIRECT("'"&$B3&"'!$D$29:$D$45"))),"NO DISPONIBLE"))} -> NO DISPONIBLE | AC3: ASEGURAMIENTO
A4: MJM-003 | B4: {=INDIRECT("'"&$B4&"'!$A$6")} -> MASA PATRÓN | C4: {=INDIRECT("'"&$B4&"'!$G$14")} -> TRUMAX | D4: {=INDIRECT("'"&$B4&"'!$G$15")} -> M1 | E4: {=INDIRECT("'"&$B4&"'!$G$16")} -> AG210753 | F4: LABORATORIO 1 | G4: OPERATIVO | H4: {=INDIRECT("'"&$B4&"'!$G$11")} -> MASA | I4: BAJA | J4: {=INDIRECT("'"&$B4&"'!$G$21")} -> 500 g | K4: {=INDIRECT("'"&$B4&"'!$G$22")} -> 500 g | L4: {=INDIRECT("'"&$B4&"'!$G$23")} -> N/A | N4: {=INDIRECT("'"&$B4&"'!$G$22")} -> 500 g | P4: {=IFERROR(LOOKUP(2,1/((INDIRECT("'"&$B4&"'!$G$29:$G$45"))<>""),(INDIRECT("'"&$B4&"'!$G$29:$G$45"))),"NO DISPONIBLE")} -> FUNCIONAL | Q4: N/A | R4: {=IF(IF(MAX((IFERROR((ROW(INDIRECT("'"&$B4&"'!$F$29:$F$45"))-ROW(INDIRECT("'"&$B4&"'!$F$29"))+1)/--(IF(INDIRECT("'"&$B4&"'!$F$29:$F$45")<>"",1,0)),0))-(IFERROR((ROW(INDIRECT("'"&$B4&"'!$F$29:$F$45"))-ROW(INDIRECT("'"&$B4&"'!$F$29"))+1)/--(FIND("VERIFICACIÓN: ", INDIRECT("'"&$B4&"'!$F$29:$F$45"))),0)))<>0,INDEX(INDIRECT("'"&$B4&"'!$A$29:$G$45"),MAX((IFERROR((ROW(INDIRECT("'"&$B4&"'!$F$29:$F$45"))-ROW(INDIRECT("'"&$B4&"'!$F$29"))+1)/--(IF(INDIRECT("'"&$B4&"'!$F$29:$F$45")<>"",1,0)),0))-(IFERROR((ROW(INDIRECT("'"&$B4&"'!$F$29:$F$45"))-ROW(INDIRECT("'"&$B4&"'!$F$29"))+1)/--(FIND("VERIFICACIÓN: ", INDIRECT("'"&$B4&"'!$F$29:$F$45"))),0))),1),0)>IF(MAX(IFERROR((_xlfn._xlws.FILTER((ROW(INDIRECT("'"&$B4&"'!$E$29:$E$45"))-ROW(INDIRECT("'"&$B4&"'!$E$29"))+1)/--(IF(INDIRECT("'"&$B4&"'!$E$29:$E$45")<>"",1,0)), NOT(ISNUMBER(MATCH((ROW(INDIRECT("'"&$B4&"'!$E$29:$E$45"))-ROW(INDIRECT("'"&$B4&"'!$E$29"))+1)/--(IF(INDIRECT("'"&$B4&"'!$E$29:$E$45")<>"",1,0)), (ROW(INDIRECT("'"&$B4&"'!$E$29:$E$45"))-ROW(INDIRECT("'"&$B4&"'!$E$29"))+1)/--(FIND("VERIFICACIÓN: ", INDIRECT("'"&$B4&"'!$E$29:$E$45"))), 0))))),0))<>0,INDEX(INDIRECT("'"&$B4&"'!$A$29:$G$45"),MAX((IFERROR((ROW(INDIRECT("'"&$B4&"'!$E$29:$E$45"))-ROW(INDIRECT("'"&$B4&"'!$E$29"))+1)/--(IF(INDIRECT("'"&$B4&"'!$E$29:$E$45")<>"",1,0)),0))-(IFERROR((ROW(INDIRECT("'"&$B4&"'!$E$29:$E$45"))-ROW(INDIRECT("'"&$B4&"'!$E$29"))+1)/--(FIND("VERIFICACIÓN: ", INDIRECT("'"&$B4&"'!$E$29:$E$45"))),0))),1),0),IF(MAX((IFERROR((ROW(INDIRECT("'"&$B4&"'!$F$29:$F$45"))-ROW(INDIRECT("'"&$B4&"'!$F$29"))+1)/--(IF(INDIRECT("'"&$B4&"'!$F$29:$F$45")<>"",1,0)),0))-(IFERROR((ROW(INDIRECT("'"&$B4&"'!$F$29:$F$45"))-ROW(INDIRECT("'"&$B4&"'!$F$29"))+1)/--(FIND("VERIFICACIÓN: ", INDIRECT("'"&$B4&"'!$F$29:$F$45"))),0)))<>0,INDEX(INDIRECT("'"&$B4&"'!$A$29:$G$45"),MAX((IFERROR((ROW(INDIRECT("'"&$B4&"'!$F$29:$F$45"))-ROW(INDIRECT("'"&$B4&"'!$F$29"))+1)/--(IF(INDIRECT("'"&$B4&"'!$F$29:$F$45")<>"",1,0)),0))-(IFERROR((ROW(INDIRECT("'"&$B4&"'!$F$29:$F$45"))-ROW(INDIRECT("'"&$B4&"'!$F$29"))+1)/--(FIND("VERIFICACIÓN: ", INDIRECT("'"&$B4&"'!$F$29:$F$45"))),0))),1),0),IF(MAX(IFERROR((_xlfn._xlws.FILTER((ROW(INDIRECT("'"&$B4&"'!$E$29:$E$45"))-ROW(INDIRECT("'"&$B4&"'!$E$29"))+1)/--(IF(INDIRECT("'"&$B4&"'!$E$29:$E$45")<>"",1,0)), NOT(ISNUMBER(MATCH((ROW(INDIRECT("'"&$B4&"'!$E$29:$E$45"))-ROW(INDIRECT("'"&$B4&"'!$E$29"))+1)/--(IF(INDIRECT("'"&$B4&"'!$E$29:$E$45")<>"",1,0)), (ROW(INDIRECT("'"&$B4&"'!$E$29:$E$45"))-ROW(INDIRECT("'"&$B4&"'!$E$29"))+1)/--(FIND("VERIFICACIÓN: ", INDIRECT("'"&$B4&"'!$E$29:$E$45"))), 0))))),0))<>0,INDEX(INDIRECT("'"&$B4&"'!$A$29:$G$45"),MAX((IFERROR((ROW(INDIRECT("'"&$B4&"'!$E$29:$E$45"))-ROW(INDIRECT("'"&$B4&"'!$E$29"))+1)/--(IF(INDIRECT("'"&$B4&"'!$E$29:$E$45")<>"",1,0)),0))-(IFERROR((ROW(INDIRECT("'"&$B4&"'!$E$29:$E$45"))-ROW(INDIRECT("'"&$B4&"'!$E$29"))+1)/--(FIND("VERIFICACIÓN: ", INDIRECT("'"&$B4&"'!$E$29:$E$45"))),0))),1),0))} -> 0 | S4: No aplica | T4: {=IF(IF(MAX((IFERROR((ROW(INDIRECT("'"&$B4&"'!$F$29:$F$45"))-ROW(INDIRECT("'"&$B4&"'!$F$29"))+1)/--(IF(INDIRECT("'"&$B4&"'!$F$29:$F$45")<>"",1,0)),0))-(IFERROR((ROW(INDIRECT("'"&$B4&"'!$F$29:$F$45"))-ROW(INDIRECT("'"&$B4&"'!$F$29"))+1)/--(FIND("VERIFICACIÓN: ", INDIRECT("'"&$B4&"'!$F$29:$F$45"))),0)))<>0,INDEX(INDIRECT("'"&$B4&"'!$A$29:$G$45"),MAX((IFERROR((ROW(INDIRECT("'"&$B4&"'!$F$29:$F$45"))-ROW(INDIRECT("'"&$B4&"'!$F$29"))+1)/--(IF(INDIRECT("'"&$B4&"'!$F$29:$F$45")<>"",1,0)),0))-(IFERROR((ROW(INDIRECT("'"&$B4&"'!$F$29:$F$45"))-ROW(INDIRECT("'"&$B4&"'!$F$29"))+1)/--(FIND("VERIFICACIÓN: ", INDIRECT("'"&$B4&"'!$F$29:$F$45"))),0))),1),0)>IF(MAX(IFERROR((_xlfn._xlws.FILTER((ROW(INDIRECT("'"&$B4&"'!$E$29:$E$45"))-ROW(INDIRECT("'"&$B4&"'!$E$29"))+1)/--(IF(INDIRECT("'"&$B4&"'!$E$29:$E$45")<>"",1,0)), NOT(ISNUMBER(MATCH((ROW(INDIRECT("'"&$B4&"'!$E$29:$E$45"))-ROW(INDIRECT("'"&$B4&"'!$E$29"))+1)/--(IF(INDIRECT("'"&$B4&"'!$E$29:$E$45")<>"",1,0)), (ROW(INDIRECT("'"&$B4&"'!$E$29:$E$45"))-ROW(INDIRECT("'"&$B4&"'!$E$29"))+1)/--(FIND("VERIFICACIÓN: ", INDIRECT("'"&$B4&"'!$E$29:$E$45"))), 0))))),0))<>0,INDEX(INDIRECT("'"&$B4&"'!$A$29:$G$45"),MAX((IFERROR((ROW(INDIRECT("'"&$B4&"'!$E$29:$E$45"))-ROW(INDIRECT("'"&$B4&"'!$E$29"))+1)/--(IF(INDIRECT("'"&$B4&"'!$E$29:$E$45")<>"",1,0)),0))-(IFERROR((ROW(INDIRECT("'"&$B4&"'!$E$29:$E$45"))-ROW(INDIRECT("'"&$B4&"'!$E$29"))+1)/--(FIND("VERIFICACIÓN: ", INDIRECT("'"&$B4&"'!$E$29:$E$45"))),0))),1),0),IF(MAX((IFERROR((ROW(INDIRECT("'"&$B4&"'!$F$29:$F$45"))-ROW(INDIRECT("'"&$B4&"'!$F$29"))+1)/--(IF(INDIRECT("'"&$B4&"'!$F$29:$F$45")<>"",1,0)),0))-(IFERROR((ROW(INDIRECT("'"&$B4&"'!$F$29:$F$45"))-ROW(INDIRECT("'"&$B4&"'!$F$29"))+1)/--(FIND("VERIFICACIÓN: ", INDIRECT("'"&$B4&"'!$F$29:$F$45"))),0)))<>0,INDEX(INDIRECT("'"&$B4&"'!$A$29:$G$45"),MAX((IFERROR((ROW(INDIRECT("'"&$B4&"'!$F$29:$F$45"))-ROW(INDIRECT("'"&$B4&"'!$F$29"))+1)/--(IF(INDIRECT("'"&$B4&"'!$F$29:$F$45")<>"",1,0)),0))-(IFERROR((ROW(INDIRECT("'"&$B4&"'!$F$29:$F$45"))-ROW(INDIRECT("'"&$B4&"'!$F$29"))+1)/--(FIND("VERIFICACIÓN: ", INDIRECT("'"&$B4&"'!$F$29:$F$45"))),0))),6),"NO DISPONIBLE"),IF(MAX(IFERROR((_xlfn._xlws.FILTER((ROW(INDIRECT("'"&$B4&"'!$E$29:$E$45"))-ROW(INDIRECT("'"&$B4&"'!$E$29"))+1)/--(IF(INDIRECT("'"&$B4&"'!$E$29:$E$45")<>"",1,0)), NOT(ISNUMBER(MATCH((ROW(INDIRECT("'"&$B4&"'!$E$29:$E$45"))-ROW(INDIRECT("'"&$B4&"'!$E$29"))+1)/--(IF(INDIRECT("'"&$B4&"'!$E$29:$E$45")<>"",1,0)), (ROW(INDIRECT("'"&$B4&"'!$E$29:$E$45"))-ROW(INDIRECT("'"&$B4&"'!$E$29"))+1)/--(FIND("VERIFICACIÓN: ", INDIRECT("'"&$B4&"'!$E$29:$E$45"))), 0))))),0))<>0,INDEX(INDIRECT("'"&$B4&"'!$A$29:$G$45"),MAX((IFERROR((ROW(INDIRECT("'"&$B4&"'!$E$29:$E$45"))-ROW(INDIRECT("'"&$B4&"'!$E$29"))+1)/--(IF(INDIRECT("'"&$B4&"'!$E$29:$E$45")<>"",1,0)),0))-(IFERROR((ROW(INDIRECT("'"&$B4&"'!$E$29:$E$45"))-ROW(INDIRECT("'"&$B4&"'!$E$29"))+1)/--(FIND("VERIFICACIÓN: ", INDIRECT("'"&$B4&"'!$E$29:$E$45"))),0))),5),"NO DISPONIBLE"))} -> NO DISPONIBLE | U4: N/A | V4: {=IF((IFERROR(VLOOKUP(IFERROR(LOOKUP(2,1/((INDIRECT("'"&$B4&"'!$F$29:$F$45"))<>""),(INDIRECT("'"&$B4&"'!$F$29:$F$45"))),"NO DISPONIBLE"),CHOOSE({1,2},(INDIRECT("'"&$B4&"'!$F$29:$F$45")),(INDIRECT("'"&$B4&"'!$A$29:$A$45"))),2,0),0))>(IFERROR(VLOOKUP(IFERROR(LOOKUP(2,1/((INDIRECT("'"&$B4&"'!$E$29:$E$45"))<>""),(INDIRECT("'"&$B4&"'!$E$29:$E$45"))),"NO DISPONIBLE"),CHOOSE({1,2},(INDIRECT("'"&$B4&"'!$E$29:$E$45")),(INDIRECT("'"&$B4&"'!$A$29:$A$45"))),2,0),0)),(IFERROR(VLOOKUP(IFERROR(LOOKUP(2,1/((INDIRECT("'"&$B4&"'!$F$29:$F$45"))<>""),(INDIRECT("'"&$B4&"'!$F$29:$F$45"))),"NO DISPONIBLE"),CHOOSE({1,2},(INDIRECT("'"&$B4&"'!$F$29:$F$45")),(INDIRECT("'"&$B4&"'!$A$29:$A$45"))),2,0),0)),(IFERROR(VLOOKUP(IFERROR(LOOKUP(2,1/((INDIRECT("'"&$B4&"'!$E$29:$E$45"))<>""),(INDIRECT("'"&$B4&"'!$E$29:$E$45"))),"NO DISPONIBLE"),CHOOSE({1,2},(INDIRECT("'"&$B4&"'!$E$29:$E$45")),(INDIRECT("'"&$B4&"'!$A$29:$A$45"))),2,0),0)))} -> 0 | W4: No aplica | X4: {=IF((IFERROR(VLOOKUP(IFERROR(LOOKUP(2,1/((INDIRECT("'"&$B4&"'!$E$29:$E$45"))<>""),(INDIRECT("'"&$B4&"'!$E$29:$E$45"))),"NO DISPONIBLE"),CHOOSE({1,2},(INDIRECT("'"&$B4&"'!$E$29:$E$45")),(INDIRECT("'"&$B4&"'!$A$29:$A$45"))),2,0),0))>(IFERROR(VLOOKUP(IFERROR(LOOKUP(2,1/((INDIRECT("'"&$B4&"'!$F$29:$F$45"))<>""),(INDIRECT("'"&$B4&"'!$F$29:$F$45"))),"NO DISPONIBLE"),CHOOSE({1,2},(INDIRECT("'"&$B4&"'!$F$29:$F$45")),(INDIRECT("'"&$B4&"'!$A$29:$A$45"))),2,0),0)),IFERROR(LOOKUP(2,1/((INDIRECT("'"&$B4&"'!$E$29:$E$45"))<>""),(INDIRECT("'"&$B4&"'!$E$29:$E$45"))),"NO DISPONIBLE"),IFERROR(LOOKUP(2,1/((INDIRECT("'"&$B4&"'!$F$29:$F$45"))<>""),(INDIRECT("'"&$B4&"'!$F$29:$F$45"))),"NO DISPONIBLE"))} -> NO DISPONIBLE | Y4: N/A | Z4: {=IF((IFERROR(VLOOKUP(IFERROR(LOOKUP(2,1/((INDIRECT("'"&$B4&"'!$D$29:$D$45"))<>""),(INDIRECT("'"&$B4&"'!$D$29:$D$45"))),"NO DISPONIBLE"),CHOOSE({1,2},(INDIRECT("'"&$B4&"'!$D$29:$D$45")),(INDIRECT("'"&$B4&"'!$A$29:$A$45"))),2,0),0))>(IFERROR(VLOOKUP(IFERROR(LOOKUP(2,1/((INDIRECT("'"&$B4&"'!$C$29:$C$45"))<>""),(INDIRECT("'"&$B4&"'!$C$29:$C$45"))),"NO DISPONIBLE"),CHOOSE({1,2},(INDIRECT("'"&$B4&"'!$C$29:$C$45")),(INDIRECT("'"&$B4&"'!$A$29:$A$45"))),2,0),0)),(IFERROR(VLOOKUP(IFERROR(LOOKUP(2,1/((INDIRECT("'"&$B4&"'!$D$29:$D$45"))<>""),(INDIRECT("'"&$B4&"'!$D$29:$D$45"))),"NO DISPONIBLE"),CHOOSE({1,2},(INDIRECT("'"&$B4&"'!$D$29:$D$45")),(INDIRECT("'"&$B4&"'!$A$29:$A$45"))),2,0),0)),(IFERROR(VLOOKUP(IFERROR(LOOKUP(2,1/((INDIRECT("'"&$B4&"'!$C$29:$C$45"))<>""),(INDIRECT("'"&$B4&"'!$C$29:$C$45"))),"NO DISPONIBLE"),CHOOSE({1,2},(INDIRECT("'"&$B4&"'!$C$29:$C$45")),(INDIRECT("'"&$B4&"'!$A$29:$A$45"))),2,0),0)))} -> 0 | AA4: No aplica | AB4: {=IF((IFERROR(VLOOKUP(IFERROR(LOOKUP(2,1/((INDIRECT("'"&$B4&"'!$C$29:$C$45"))<>""),(INDIRECT("'"&$B4&"'!$C$29:$C$45"))),"NO DISPONIBLE"),CHOOSE({1,2},(INDIRECT("'"&$B4&"'!$C$29:$C$45")),(INDIRECT("'"&$B4&"'!$A$29:$A$45"))),2,0),0))>(IFERROR(VLOOKUP(IFERROR(LOOKUP(2,1/((INDIRECT("'"&$B4&"'!$D$29:$D$45"))<>""),(INDIRECT("'"&$B4&"'!$D$29:$D$45"))),"NO DISPONIBLE"),CHOOSE({1,2},(INDIRECT("'"&$B4&"'!$D$29:$D$45")),(INDIRECT("'"&$B4&"'!$A$29:$A$45"))),2,0),0)),IFERROR(LOOKUP(2,1/((INDIRECT("'"&$B4&"'!$C$29:$C$45"))<>""),(INDIRECT("'"&$B4&"'!$C$29:$C$45"))),"NO DISPONIBLE"),IFERROR(LOOKUP(2,1/((INDIRECT("'"&$B4&"'!$D$29:$D$45"))<>""),(INDIRECT("'"&$B4&"'!$D$29:$D$45"))),"NO DISPONIBLE"))} -> NO DISPONIBLE | AC4: ASEGURAMIENTO
A5: MJM-004 | B5: {=INDIRECT("'"&$B5&"'!$A$6")} -> MASA PATRÓN | C5: {=INDIRECT("'"&$B5&"'!$G$14")} -> TRUMAX | D5: {=INDIRECT("'"&$B5&"'!$G$15")} -> M1 | E5: {=INDIRECT("'"&$B5&"'!$G$16")} -> AG210617 | F5: LABORATORIO 1 | G5: OPERATIVO | H5: {=INDIRECT("'"&$B5&"'!$G$11")} -> MASA | I5: BAJA | J5: {=INDIRECT("'"&$B5&"'!$G$21")} -> 1 kg | K5: {=INDIRECT("'"&$B5&"'!$G$22")} -> 1 kg | L5: {=INDIRECT("'"&$B5&"'!$G$23")} -> N/A | N5: {=INDIRECT("'"&$B5&"'!$G$22")} -> 1 kg | P5: {=IFERROR(LOOKUP(2,1/((INDIRECT("'"&$B5&"'!$G$29:$G$45"))<>""),(INDIRECT("'"&$B5&"'!$G$29:$G$45"))),"NO DISPONIBLE")} -> FUNCIONAL | Q5: N/A | R5: {=IF(IF(MAX((IFERROR((ROW(INDIRECT("'"&$B5&"'!$F$29:$F$45"))-ROW(INDIRECT("'"&$B5&"'!$F$29"))+1)/--(IF(INDIRECT("'"&$B5&"'!$F$29:$F$45")<>"",1,0)),0))-(IFERROR((ROW(INDIRECT("'"&$B5&"'!$F$29:$F$45"))-ROW(INDIRECT("'"&$B5&"'!$F$29"))+1)/--(FIND("VERIFICACIÓN: ", INDIRECT("'"&$B5&"'!$F$29:$F$45"))),0)))<>0,INDEX(INDIRECT("'"&$B5&"'!$A$29:$G$45"),MAX((IFERROR((ROW(INDIRECT("'"&$B5&"'!$F$29:$F$45"))-ROW(INDIRECT("'"&$B5&"'!$F$29"))+1)/--(IF(INDIRECT("'"&$B5&"'!$F$29:$F$45")<>"",1,0)),0))-(IFERROR((ROW(INDIRECT("'"&$B5&"'!$F$29:$F$45"))-ROW(INDIRECT("'"&$B5&"'!$F$29"))+1)/--(FIND("VERIFICACIÓN: ", INDIRECT("'"&$B5&"'!$F$29:$F$45"))),0))),1),0)>IF(MAX(IFERROR((_xlfn._xlws.FILTER((ROW(INDIRECT("'"&$B5&"'!$E$29:$E$45"))-ROW(INDIRECT("'"&$B5&"'!$E$29"))+1)/--(IF(INDIRECT("'"&$B5&"'!$E$29:$E$45")<>"",1,0)), NOT(ISNUMBER(MATCH((ROW(INDIRECT("'"&$B5&"'!$E$29:$E$45"))-ROW(INDIRECT("'"&$B5&"'!$E$29"))+1)/--(IF(INDIRECT("'"&$B5&"'!$E$29:$E$45")<>"",1,0)), (ROW(INDIRECT("'"&$B5&"'!$E$29:$E$45"))-ROW(INDIRECT("'"&$B5&"'!$E$29"))+1)/--(FIND("VERIFICACIÓN: ", INDIRECT("'"&$B5&"'!$E$29:$E$45"))), 0))))),0))<>0,INDEX(INDIRECT("'"&$B5&"'!$A$29:$G$45"),MAX((IFERROR((ROW(INDIRECT("'"&$B5&"'!$E$29:$E$45"))-ROW(INDIRECT("'"&$B5&"'!$E$29"))+1)/--(IF(INDIRECT("'"&$B5&"'!$E$29:$E$45")<>"",1,0)),0))-(IFERROR((ROW(INDIRECT("'"&$B5&"'!$E$29:$E$45"))-ROW(INDIRECT("'"&$B5&"'!$E$29"))+1)/--(FIND("VERIFICACIÓN: ", INDIRECT("'"&$B5&"'!$E$29:$E$45"))),0))),1),0),IF(MAX((IFERROR((ROW(INDIRECT("'"&$B5&"'!$F$29:$F$45"))-ROW(INDIRECT("'"&$B5&"'!$F$29"))+1)/--(IF(INDIRECT("'"&$B5&"'!$F$29:$F$45")<>"",1,0)),0))-(IFERROR((ROW(INDIRECT("'"&$B5&"'!$F$29:$F$45"))-ROW(INDIRECT("'"&$B5&"'!$F$29"))+1)/--(FIND("VERIFICACIÓN: ", INDIRECT("'"&$B5&"'!$F$29:$F$45"))),0)))<>0,INDEX(INDIRECT("'"&$B5&"'!$A$29:$G$45"),MAX((IFERROR((ROW(INDIRECT("'"&$B5&"'!$F$29:$F$45"))-ROW(INDIRECT("'"&$B5&"'!$F$29"))+1)/--(IF(INDIRECT("'"&$B5&"'!$F$29:$F$45")<>"",1,0)),0))-(IFERROR((ROW(INDIRECT("'"&$B5&"'!$F$29:$F$45"))-ROW(INDIRECT("'"&$B5&"'!$F$29"))+1)/--(FIND("VERIFICACIÓN: ", INDIRECT("'"&$B5&"'!$F$29:$F$45"))),0))),1),0),IF(MAX(IFERROR((_xlfn._xlws.FILTER((ROW(INDIRECT("'"&$B5&"'!$E$29:$E$45"))-ROW(INDIRECT("'"&$B5&"'!$E$29"))+1)/--(IF(INDIRECT("'"&$B5&"'!$E$29:$E$45")<>"",1,0)), NOT(ISNUMBER(MATCH((ROW(INDIRECT("'"&$B5&"'!$E$29:$E$45"))-ROW(INDIRECT("'"&$B5&"'!$E$29"))+1)/--(IF(INDIRECT("'"&$B5&"'!$E$29:$E$45")<>"",1,0)), (ROW(INDIRECT("'"&$B5&"'!$E$29:$E$45"))-ROW(INDIRECT("'"&$B5&"'!$E$29"))+1)/--(FIND("VERIFICACIÓN: ", INDIRECT("'"&$B5&"'!$E$29:$E$45"))), 0))))),0))<>0,INDEX(INDIRECT("'"&$B5&"'!$A$29:$G$45"),MAX((IFERROR((ROW(INDIRECT("'"&$B5&"'!$E$29:$E$45"))-ROW(INDIRECT("'"&$B5&"'!$E$29"))+1)/--(IF(INDIRECT("'"&$B5&"'!$E$29:$E$45")<>"",1,0)),0))-(IFERROR((ROW(INDIRECT("'"&$B5&"'!$E$29:$E$45"))-ROW(INDIRECT("'"&$B5&"'!$E$29"))+1)/--(FIND("VERIFICACIÓN: ", INDIRECT("'"&$B5&"'!$E$29:$E$45"))),0))),1),0))} -> 0 | S5: No aplica | T5: {=IF(IF(MAX((IFERROR((ROW(INDIRECT("'"&$B5&"'!$F$29:$F$45"))-ROW(INDIRECT("'"&$B5&"'!$F$29"))+1)/--(IF(INDIRECT("'"&$B5&"'!$F$29:$F$45")<>"",1,0)),0))-(IFERROR((ROW(INDIRECT("'"&$B5&"'!$F$29:$F$45"))-ROW(INDIRECT("'"&$B5&"'!$F$29"))+1)/--(FIND("VERIFICACIÓN: ", INDIRECT("'"&$B5&"'!$F$29:$F$45"))),0)))<>0,INDEX(INDIRECT("'"&$B5&"'!$A$29:$G$45"),MAX((IFERROR((ROW(INDIRECT("'"&$B5&"'!$F$29:$F$45"))-ROW(INDIRECT("'"&$B5&"'!$F$29"))+1)/--(IF(INDIRECT("'"&$B5&"'!$F$29:$F$45")<>"",1,0)),0))-(IFERROR((ROW(INDIRECT("'"&$B5&"'!$F$29:$F$45"))-ROW(INDIRECT("'"&$B5&"'!$F$29"))+1)/--(FIND("VERIFICACIÓN: ", INDIRECT("'"&$B5&"'!$F$29:$F$45"))),0))),1),0)>IF(MAX(IFERROR((_xlfn._xlws.FILTER((ROW(INDIRECT("'"&$B5&"'!$E$29:$E$45"))-ROW(INDIRECT("'"&$B5&"'!$E$29"))+1)/--(IF(INDIRECT("'"&$B5&"'!$E$29:$E$45")<>"",1,0)), NOT(ISNUMBER(MATCH((ROW(INDIRECT("'"&$B5&"'!$E$29:$E$45"))-ROW(INDIRECT("'"&$B5&"'!$E$29"))+1)/--(IF(INDIRECT("'"&$B5&"'!$E$29:$E$45")<>"",1,0)), (ROW(INDIRECT("'"&$B5&"'!$E$29:$E$45"))-ROW(INDIRECT("'"&$B5&"'!$E$29"))+1)/--(FIND("VERIFICACIÓN: ", INDIRECT("'"&$B5&"'!$E$29:$E$45"))), 0))))),0))<>0,INDEX(INDIRECT("'"&$B5&"'!$A$29:$G$45"),MAX((IFERROR((ROW(INDIRECT("'"&$B5&"'!$E$29:$E$45"))-ROW(INDIRECT("'"&$B5&"'!$E$29"))+1)/--(IF(INDIRECT("'"&$B5&"'!$E$29:$E$45")<>"",1,0)),0))-(IFERROR((ROW(INDIRECT("'"&$B5&"'!$E$29:$E$45"))-ROW(INDIRECT("'"&$B5&"'!$E$29"))+1)/--(FIND("VERIFICACIÓN: ", INDIRECT("'"&$B5&"'!$E$29:$E$45"))),0))),1),0),IF(MAX((IFERROR((ROW(INDIRECT("'"&$B5&"'!$F$29:$F$45"))-ROW(INDIRECT("'"&$B5&"'!$F$29"))+1)/--(IF(INDIRECT("'"&$B5&"'!$F$29:$F$45")<>"",1,0)),0))-(IFERROR((ROW(INDIRECT("'"&$B5&"'!$F$29:$F$45"))-ROW(INDIRECT("'"&$B5&"'!$F$29"))+1)/--(FIND("VERIFICACIÓN: ", INDIRECT("'"&$B5&"'!$F$29:$F$45"))),0)))<>0,INDEX(INDIRECT("'"&$B5&"'!$A$29:$G$45"),MAX((IFERROR((ROW(INDIRECT("'"&$B5&"'!$F$29:$F$45"))-ROW(INDIRECT("'"&$B5&"'!$F$29"))+1)/--(IF(INDIRECT("'"&$B5&"'!$F$29:$F$45")<>"",1,0)),0))-(IFERROR((ROW(INDIRECT("'"&$B5&"'!$F$29:$F$45"))-ROW(INDIRECT("'"&$B5&"'!$F$29"))+1)/--(FIND("VERIFICACIÓN: ", INDIRECT("'"&$B5&"'!$F$29:$F$45"))),0))),6),"NO DISPONIBLE"),IF(MAX(IFERROR((_xlfn._xlws.FILTER((ROW(INDIRECT("'"&$B5&"'!$E$29:$E$45"))-ROW(INDIRECT("'"&$B5&"'!$E$29"))+1)/--(IF(INDIRECT("'"&$B5&"'!$E$29:$E$45")<>"",1,0)), NOT(ISNUMBER(MATCH((ROW(INDIRECT("'"&$B5&"'!$E$29:$E$45"))-ROW(INDIRECT("'"&$B5&"'!$E$29"))+1)/--(IF(INDIRECT("'"&$B5&"'!$E$29:$E$45")<>"",1,0)), (ROW(INDIRECT("'"&$B5&"'!$E$29:$E$45"))-ROW(INDIRECT("'"&$B5&"'!$E$29"))+1)/--(FIND("VERIFICACIÓN: ", INDIRECT("'"&$B5&"'!$E$29:$E$45"))), 0))))),0))<>0,INDEX(INDIRECT("'"&$B5&"'!$A$29:$G$45"),MAX((IFERROR((ROW(INDIRECT("'"&$B5&"'!$E$29:$E$45"))-ROW(INDIRECT("'"&$B5&"'!$E$29"))+1)/--(IF(INDIRECT("'"&$B5&"'!$E$29:$E$45")<>"",1,0)),0))-(IFERROR((ROW(INDIRECT("'"&$B5&"'!$E$29:$E$45"))-ROW(INDIRECT("'"&$B5&"'!$E$29"))+1)/--(FIND("VERIFICACIÓN: ", INDIRECT("'"&$B5&"'!$E$29:$E$45"))),0))),5),"NO DISPONIBLE"))} -> NO DISPONIBLE | U5: N/A | V5: {=IF((IFERROR(VLOOKUP(IFERROR(LOOKUP(2,1/((INDIRECT("'"&$B5&"'!$F$29:$F$45"))<>""),(INDIRECT("'"&$B5&"'!$F$29:$F$45"))),"NO DISPONIBLE"),CHOOSE({1,2},(INDIRECT("'"&$B5&"'!$F$29:$F$45")),(INDIRECT("'"&$B5&"'!$A$29:$A$45"))),2,0),0))>(IFERROR(VLOOKUP(IFERROR(LOOKUP(2,1/((INDIRECT("'"&$B5&"'!$E$29:$E$45"))<>""),(INDIRECT("'"&$B5&"'!$E$29:$E$45"))),"NO DISPONIBLE"),CHOOSE({1,2},(INDIRECT("'"&$B5&"'!$E$29:$E$45")),(INDIRECT("'"&$B5&"'!$A$29:$A$45"))),2,0),0)),(IFERROR(VLOOKUP(IFERROR(LOOKUP(2,1/((INDIRECT("'"&$B5&"'!$F$29:$F$45"))<>""),(INDIRECT("'"&$B5&"'!$F$29:$F$45"))),"NO DISPONIBLE"),CHOOSE({1,2},(INDIRECT("'"&$B5&"'!$F$29:$F$45")),(INDIRECT("'"&$B5&"'!$A$29:$A$45"))),2,0),0)),(IFERROR(VLOOKUP(IFERROR(LOOKUP(2,1/((INDIRECT("'"&$B5&"'!$E$29:$E$45"))<>""),(INDIRECT("'"&$B5&"'!$E$29:$E$45"))),"NO DISPONIBLE"),CHOOSE({1,2},(INDIRECT("'"&$B5&"'!$E$29:$E$45")),(INDIRECT("'"&$B5&"'!$A$29:$A$45"))),2,0),0)))} -> 0 | W5: No aplica | X5: {=IF((IFERROR(VLOOKUP(IFERROR(LOOKUP(2,1/((INDIRECT("'"&$B5&"'!$E$29:$E$45"))<>""),(INDIRECT("'"&$B5&"'!$E$29:$E$45"))),"NO DISPONIBLE"),CHOOSE({1,2},(INDIRECT("'"&$B5&"'!$E$29:$E$45")),(INDIRECT("'"&$B5&"'!$A$29:$A$45"))),2,0),0))>(IFERROR(VLOOKUP(IFERROR(LOOKUP(2,1/((INDIRECT("'"&$B5&"'!$F$29:$F$45"))<>""),(INDIRECT("'"&$B5&"'!$F$29:$F$45"))),"NO DISPONIBLE"),CHOOSE({1,2},(INDIRECT("'"&$B5&"'!$F$29:$F$45")),(INDIRECT("'"&$B5&"'!$A$29:$A$45"))),2,0),0)),IFERROR(LOOKUP(2,1/((INDIRECT("'"&$B5&"'!$E$29:$E$45"))<>""),(INDIRECT("'"&$B5&"'!$E$29:$E$45"))),"NO DISPONIBLE"),IFERROR(LOOKUP(2,1/((INDIRECT("'"&$B5&"'!$F$29:$F$45"))<>""),(INDIRECT("'"&$B5&"'!$F$29:$F$45"))),"NO DISPONIBLE"))} -> NO DISPONIBLE | Y5: N/A | Z5: {=IF((IFERROR(VLOOKUP(IFERROR(LOOKUP(2,1/((INDIRECT("'"&$B5&"'!$D$29:$D$45"))<>""),(INDIRECT("'"&$B5&"'!$D$29:$D$45"))),"NO DISPONIBLE"),CHOOSE({1,2},(INDIRECT("'"&$B5&"'!$D$29:$D$45")),(INDIRECT("'"&$B5&"'!$A$29:$A$45"))),2,0),0))>(IFERROR(VLOOKUP(IFERROR(LOOKUP(2,1/((INDIRECT("'"&$B5&"'!$C$29:$C$45"))<>""),(INDIRECT("'"&$B5&"'!$C$29:$C$45"))),"NO DISPONIBLE"),CHOOSE({1,2},(INDIRECT("'"&$B5&"'!$C$29:$C$45")),(INDIRECT("'"&$B5&"'!$A$29:$A$45"))),2,0),0)),(IFERROR(VLOOKUP(IFERROR(LOOKUP(2,1/((INDIRECT("'"&$B5&"'!$D$29:$D$45"))<>""),(INDIRECT("'"&$B5&"'!$D$29:$D$45"))),"NO DISPONIBLE"),CHOOSE({1,2},(INDIRECT("'"&$B5&"'!$D$29:$D$45")),(INDIRECT("'"&$B5&"'!$A$29:$A$45"))),2,0),0)),(IFERROR(VLOOKUP(IFERROR(LOOKUP(2,1/((INDIRECT("'"&$B5&"'!$C$29:$C$45"))<>""),(INDIRECT("'"&$B5&"'!$C$29:$C$45"))),"NO DISPONIBLE"),CHOOSE({1,2},(INDIRECT("'"&$B5&"'!$C$29:$C$45")),(INDIRECT("'"&$B5&"'!$A$29:$A$45"))),2,0),0)))} -> 0 | AA5: No aplica | AB5: {=IF((IFERROR(VLOOKUP(IFERROR(LOOKUP(2,1/((INDIRECT("'"&$B5&"'!$C$29:$C$45"))<>""),(INDIRECT("'"&$B5&"'!$C$29:$C$45"))),"NO DISPONIBLE"),CHOOSE({1,2},(INDIRECT("'"&$B5&"'!$C$29:$C$45")),(INDIRECT("'"&$B5&"'!$A$29:$A$45"))),2,0),0))>(IFERROR(VLOOKUP(IFERROR(LOOKUP(2,1/((INDIRECT("'"&$B5&"'!$D$29:$D$45"))<>""),(INDIRECT("'"&$B5&"'!$D$29:$D$45"))),"NO DISPONIBLE"),CHOOSE({1,2},(INDIRECT("'"&$B5&"'!$D$29:$D$45")),(INDIRECT("'"&$B5&"'!$A$29:$A$45"))),2,0),0)),IFERROR(LOOKUP(2,1/((INDIRECT("'"&$B5&"'!$C$29:$C$45"))<>""),(INDIRECT("'"&$B5&"'!$C$29:$C$45"))),"NO DISPONIBLE"),IFERROR(LOOKUP(2,1/((INDIRECT("'"&$B5&"'!$D$29:$D$45"))<>""),(INDIRECT("'"&$B5&"'!$D$29:$D$45"))),"NO DISPONIBLE"))} -> NO DISPONIBLE | AC5: ASEGURAMIENTO
A6: MJM-005 | B6: {=INDIRECT("'"&$B6&"'!$A$6")} -> MASA PATRÓN | C6: {=INDIRECT("'"&$B6&"'!$G$14")} -> COLMETRO | D6: {=INDIRECT("'"&$B6&"'!$G$15")} -> NO PORTA | E6: {=INDIRECT("'"&$B6&"'!$G$16")} -> NO PORTA | F6: LABORATORIO 1 | G6: OPERATIVO | H6: {=INDIRECT("'"&$B6&"'!$G$11")} -> MASA | I6: BAJA | J6: {=INDIRECT("'"&$B6&"'!$G$21")} -> 5 kg | K6: {=INDIRECT("'"&$B6&"'!$G$22")} -> 5 kg | L6: {=INDIRECT("'"&$B6&"'!$G$23")} -> N/A | N6: {=INDIRECT("'"&$B6&"'!$G$22")} -> 5 kg | P6: {=IFERROR(LOOKUP(2,1/((INDIRECT("'"&$B6&"'!$G$29:$G$45"))<>""),(INDIRECT("'"&$B6&"'!$G$29:$G$45"))),"NO DISPONIBLE")} -> FUNCIONAL | Q6: N/A | R6: {=IF(IF(MAX((IFERROR((ROW(INDIRECT("'"&$B6&"'!$F$29:$F$45"))-ROW(INDIRECT("'"&$B6&"'!$F$29"))+1)/--(IF(INDIRECT("'"&$B6&"'!$F$29:$F$45")<>"",1,0)),0))-(IFERROR((ROW(INDIRECT("'"&$B6&"'!$F$29:$F$45"))-ROW(INDIRECT("'"&$B6&"'!$F$29"))+1)/--(FIND("VERIFICACIÓN: ", INDIRECT("'"&$B6&"'!$F$29:$F$45"))),0)))<>0,INDEX(INDIRECT("'"&$B6&"'!$A$29:$G$45"),MAX((IFERROR((ROW(INDIRECT("'"&$B6&"'!$F$29:$F$45"))-ROW(INDIRECT("'"&$B6&"'!$F$29"))+1)/--(IF(INDIRECT("'"&$B6&"'!$F$29:$F$45")<>"",1,0)),0))-(IFERROR((ROW(INDIRECT("'"&$B6&"'!$F$29:$F$45"))-ROW(INDIRECT("'"&$B6&"'!$F$29"))+1)/--(FIND("VERIFICACIÓN: ", INDIRECT("'"&$B6&"'!$F$29:$F$45"))),0))),1),0)>IF(MAX(IFERROR((_xlfn._xlws.FILTER((ROW(INDIRECT("'"&$B6&"'!$E$29:$E$45"))-ROW(INDIRECT("'"&$B6&"'!$E$29"))+1)/--(IF(INDIRECT("'"&$B6&"'!$E$29:$E$45")<>"",1,0)), NOT(ISNUMBER(MATCH((ROW(INDIRECT("'"&$B6&"'!$E$29:$E$45"))-ROW(INDIRECT("'"&$B6&"'!$E$29"))+1)/--(IF(INDIRECT("'"&$B6&"'!$E$29:$E$45")<>"",1,0)), (ROW(INDIRECT("'"&$B6&"'!$E$29:$E$45"))-ROW(INDIRECT("'"&$B6&"'!$E$29"))+1)/--(FIND("VERIFICACIÓN: ", INDIRECT("'"&$B6&"'!$E$29:$E$45"))), 0))))),0))<>0,INDEX(INDIRECT("'"&$B6&"'!$A$29:$G$45"),MAX((IFERROR((ROW(INDIRECT("'"&$B6&"'!$E$29:$E$45"))-ROW(INDIRECT("'"&$B6&"'!$E$29"))+1)/--(IF(INDIRECT("'"&$B6&"'!$E$29:$E$45")<>"",1,0)),0))-(IFERROR((ROW(INDIRECT("'"&$B6&"'!$E$29:$E$45"))-ROW(INDIRECT("'"&$B6&"'!$E$29"))+1)/--(FIND("VERIFICACIÓN: ", INDIRECT("'"&$B6&"'!$E$29:$E$45"))),0))),1),0),IF(MAX((IFERROR((ROW(INDIRECT("'"&$B6&"'!$F$29:$F$45"))-ROW(INDIRECT("'"&$B6&"'!$F$29"))+1)/--(IF(INDIRECT("'"&$B6&"'!$F$29:$F$45")<>"",1,0)),0))-(IFERROR((ROW(INDIRECT("'"&$B6&"'!$F$29:$F$45"))-ROW(INDIRECT("'"&$B6&"'!$F$29"))+1)/--(FIND("VERIFICACIÓN: ", INDIRECT("'"&$B6&"'!$F$29:$F$45"))),0)))<>0,INDEX(INDIRECT("'"&$B6&"'!$A$29:$G$45"),MAX((IFERROR((ROW(INDIRECT("'"&$B6&"'!$F$29:$F$45"))-ROW(INDIRECT("'"&$B6&"'!$F$29"))+1)/--(IF(INDIRECT("'"&$B6&"'!$F$29:$F$45")<>"",1,0)),0))-(IFERROR((ROW(INDIRECT("'"&$B6&"'!$F$29:$F$45"))-ROW(INDIRECT("'"&$B6&"'!$F$29"))+1)/--(FIND("VERIFICACIÓN: ", INDIRECT("'"&$B6&"'!$F$29:$F$45"))),0))),1),0),IF(MAX(IFERROR((_xlfn._xlws.FILTER((ROW(INDIRECT("'"&$B6&"'!$E$29:$E$45"))-ROW(INDIRECT("'"&$B6&"'!$E$29"))+1)/--(IF(INDIRECT("'"&$B6&"'!$E$29:$E$45")<>"",1,0)), NOT(ISNUMBER(MATCH((ROW(INDIRECT("'"&$B6&"'!$E$29:$E$45"))-ROW(INDIRECT("'"&$B6&"'!$E$29"))+1)/--(IF(INDIRECT("'"&$B6&"'!$E$29:$E$45")<>"",1,0)), (ROW(INDIRECT("'"&$B6&"'!$E$29:$E$45"))-ROW(INDIRECT("'"&$B6&"'!$E$29"))+1)/--(FIND("VERIFICACIÓN: ", INDIRECT("'"&$B6&"'!$E$29:$E$45"))), 0))))),0))<>0,INDEX(INDIRECT("'"&$B6&"'!$A$29:$G$45"),MAX((IFERROR((ROW(INDIRECT("'"&$B6&"'!$E$29:$E$45"))-ROW(INDIRECT("'"&$B6&"'!$E$29"))+1)/--(IF(INDIRECT("'"&$B6&"'!$E$29:$E$45")<>"",1,0)),0))-(IFERROR((ROW(INDIRECT("'"&$B6&"'!$E$29:$E$45"))-ROW(INDIRECT("'"&$B6&"'!$E$29"))+1)/--(FIND("VERIFICACIÓN: ", INDIRECT("'"&$B6&"'!$E$29:$E$45"))),0))),1),0))} -> 0 | S6: No aplica | T6: {=IF(IF(MAX((IFERROR((ROW(INDIRECT("'"&$B6&"'!$F$29:$F$45"))-ROW(INDIRECT("'"&$B6&"'!$F$29"))+1)/--(IF(INDIRECT("'"&$B6&"'!$F$29:$F$45")<>"",1,0)),0))-(IFERROR((ROW(INDIRECT("'"&$B6&"'!$F$29:$F$45"))-ROW(INDIRECT("'"&$B6&"'!$F$29"))+1)/--(FIND("VERIFICACIÓN: ", INDIRECT("'"&$B6&"'!$F$29:$F$45"))),0)))<>0,INDEX(INDIRECT("'"&$B6&"'!$A$29:$G$45"),MAX((IFERROR((ROW(INDIRECT("'"&$B6&"'!$F$29:$F$45"))-ROW(INDIRECT("'"&$B6&"'!$F$29"))+1)/--(IF(INDIRECT("'"&$B6&"'!$F$29:$F$45")<>"",1,0)),0))-(IFERROR((ROW(INDIRECT("'"&$B6&"'!$F$29:$F$45"))-ROW(INDIRECT("'"&$B6&"'!$F$29"))+1)/--(FIND("VERIFICACIÓN: ", INDIRECT("'"&$B6&"'!$F$29:$F$45"))),0))),1),0)>IF(MAX(IFERROR((_xlfn._xlws.FILTER((ROW(INDIRECT("'"&$B6&"'!$E$29:$E$45"))-ROW(INDIRECT("'"&$B6&"'!$E$29"))+1)/--(IF(INDIRECT("'"&$B6&"'!$E$29:$E$45")<>"",1,0)), NOT(ISNUMBER(MATCH((ROW(INDIRECT("'"&$B6&"'!$E$29:$E$45"))-ROW(INDIRECT("'"&$B6&"'!$E$29"))+1)/--(IF(INDIRECT("'"&$B6&"'!$E$29:$E$45")<>"",1,0)), (ROW(INDIRECT("'"&$B6&"'!$E$29:$E$45"))-ROW(INDIRECT("'"&$B6&"'!$E$29"))+1)/--(FIND("VERIFICACIÓN: ", INDIRECT("'"&$B6&"'!$E$29:$E$45"))), 0))))),0))<>0,INDEX(INDIRECT("'"&$B6&"'!$A$29:$G$45"),MAX((IFERROR((ROW(INDIRECT("'"&$B6&"'!$E$29:$E$45"))-ROW(INDIRECT("'"&$B6&"'!$E$29"))+1)/--(IF(INDIRECT("'"&$B6&"'!$E$29:$E$45")<>"",1,0)),0))-(IFERROR((ROW(INDIRECT("'"&$B6&"'!$E$29:$E$45"))-ROW(INDIRECT("'"&$B6&"'!$E$29"))+1)/--(FIND("VERIFICACIÓN: ", INDIRECT("'"&$B6&"'!$E$29:$E$45"))),0))),1),0),IF(MAX((IFERROR((ROW(INDIRECT("'"&$B6&"'!$F$29:$F$45"))-ROW(INDIRECT("'"&$B6&"'!$F$29"))+1)/--(IF(INDIRECT("'"&$B6&"'!$F$29:$F$45")<>"",1,0)),0))-(IFERROR((ROW(INDIRECT("'"&$B6&"'!$F$29:$F$45"))-ROW(INDIRECT("'"&$B6&"'!$F$29"))+1)/--(FIND("VERIFICACIÓN: ", INDIRECT("'"&$B6&"'!$F$29:$F$45"))),0)))<>0,INDEX(INDIRECT("'"&$B6&"'!$A$29:$G$45"),MAX((IFERROR((ROW(INDIRECT("'"&$B6&"'!$F$29:$F$45"))-ROW(INDIRECT("'"&$B6&"'!$F$29"))+1)/--(IF(INDIRECT("'"&$B6&"'!$F$29:$F$45")<>"",1,0)),0))-(IFERROR((ROW(INDIRECT("'"&$B6&"'!$F$29:$F$45"))-ROW(INDIRECT("'"&$B6&"'!$F$29"))+1)/--(FIND("VERIFICACIÓN: ", INDIRECT("'"&$B6&"'!$F$29:$F$45"))),0))),6),"NO DISPONIBLE"),IF(MAX(IFERROR((_xlfn._xlws.FILTER((ROW(INDIRECT("'"&$B6&"'!$E$29:$E$45"))-ROW(INDIRECT("'"&$B6&"'!$E$29"))+1)/--(IF(INDIRECT("'"&$B6&"'!$E$29:$E$45")<>"",1,0)), NOT(ISNUMBER(MATCH((ROW(INDIRECT("'"&$B6&"'!$E$29:$E$45"))-ROW(INDIRECT("'"&$B6&"'!$E$29"))+1)/--(IF(INDIRECT("'"&$B6&"'!$E$29:$E$45")<>"",1,0)), (ROW(INDIRECT("'"&$B6&"'!$E$29:$E$45"))-ROW(INDIRECT("'"&$B6&"'!$E$29"))+1)/--(FIND("VERIFICACIÓN: ", INDIRECT("'"&$B6&"'!$E$29:$E$45"))), 0))))),0))<>0,INDEX(INDIRECT("'"&$B6&"'!$A$29:$G$45"),MAX((IFERROR((ROW(INDIRECT("'"&$B6&"'!$E$29:$E$45"))-ROW(INDIRECT("'"&$B6&"'!$E$29"))+1)/--(IF(INDIRECT("'"&$B6&"'!$E$29:$E$45")<>"",1,0)),0))-(IFERROR((ROW(INDIRECT("'"&$B6&"'!$E$29:$E$45"))-ROW(INDIRECT("'"&$B6&"'!$E$29"))+1)/--(FIND("VERIFICACIÓN: ", INDIRECT("'"&$B6&"'!$E$29:$E$45"))),0))),5),"NO DISPONIBLE"))} -> NO DISPONIBLE | U6: N/A | V6: {=IF((IFERROR(VLOOKUP(IFERROR(LOOKUP(2,1/((INDIRECT("'"&$B6&"'!$F$29:$F$45"))<>""),(INDIRECT("'"&$B6&"'!$F$29:$F$45"))),"NO DISPONIBLE"),CHOOSE({1,2},(INDIRECT("'"&$B6&"'!$F$29:$F$45")),(INDIRECT("'"&$B6&"'!$A$29:$A$45"))),2,0),0))>(IFERROR(VLOOKUP(IFERROR(LOOKUP(2,1/((INDIRECT("'"&$B6&"'!$E$29:$E$45"))<>""),(INDIRECT("'"&$B6&"'!$E$29:$E$45"))),"NO DISPONIBLE"),CHOOSE({1,2},(INDIRECT("'"&$B6&"'!$E$29:$E$45")),(INDIRECT("'"&$B6&"'!$A$29:$A$45"))),2,0),0)),(IFERROR(VLOOKUP(IFERROR(LOOKUP(2,1/((INDIRECT("'"&$B6&"'!$F$29:$F$45"))<>""),(INDIRECT("'"&$B6&"'!$F$29:$F$45"))),"NO DISPONIBLE"),CHOOSE({1,2},(INDIRECT("'"&$B6&"'!$F$29:$F$45")),(INDIRECT("'"&$B6&"'!$A$29:$A$45"))),2,0),0)),(IFERROR(VLOOKUP(IFERROR(LOOKUP(2,1/((INDIRECT("'"&$B6&"'!$E$29:$E$45"))<>""),(INDIRECT("'"&$B6&"'!$E$29:$E$45"))),"NO DISPONIBLE"),CHOOSE({1,2},(INDIRECT("'"&$B6&"'!$E$29:$E$45")),(INDIRECT("'"&$B6&"'!$A$29:$A$45"))),2,0),0)))} -> 0 | W6: No aplica | X6: {=IF((IFERROR(VLOOKUP(IFERROR(LOOKUP(2,1/((INDIRECT("'"&$B6&"'!$E$29:$E$45"))<>""),(INDIRECT("'"&$B6&"'!$E$29:$E$45"))),"NO DISPONIBLE"),CHOOSE({1,2},(INDIRECT("'"&$B6&"'!$E$29:$E$45")),(INDIRECT("'"&$B6&"'!$A$29:$A$45"))),2,0),0))>(IFERROR(VLOOKUP(IFERROR(LOOKUP(2,1/((INDIRECT("'"&$B6&"'!$F$29:$F$45"))<>""),(INDIRECT("'"&$B6&"'!$F$29:$F$45"))),"NO DISPONIBLE"),CHOOSE({1,2},(INDIRECT("'"&$B6&"'!$F$29:$F$45")),(INDIRECT("'"&$B6&"'!$A$29:$A$45"))),2,0),0)),IFERROR(LOOKUP(2,1/((INDIRECT("'"&$B6&"'!$E$29:$E$45"))<>""),(INDIRECT("'"&$B6&"'!$E$29:$E$45"))),"NO DISPONIBLE"),IFERROR(LOOKUP(2,1/((INDIRECT("'"&$B6&"'!$F$29:$F$45"))<>""),(INDIRECT("'"&$B6&"'!$F$29:$F$45"))),"NO DISPONIBLE"))} -> NO DISPONIBLE | Y6: N/A | Z6: {=IF((IFERROR(VLOOKUP(IFERROR(LOOKUP(2,1/((INDIRECT("'"&$B6&"'!$D$29:$D$45"))<>""),(INDIRECT("'"&$B6&"'!$D$29:$D$45"))),"NO DISPONIBLE"),CHOOSE({1,2},(INDIRECT("'"&$B6&"'!$D$29:$D$45")),(INDIRECT("'"&$B6&"'!$A$29:$A$45"))),2,0),0))>(IFERROR(VLOOKUP(IFERROR(LOOKUP(2,1/((INDIRECT("'"&$B6&"'!$C$29:$C$45"))<>""),(INDIRECT("'"&$B6&"'!$C$29:$C$45"))),"NO DISPONIBLE"),CHOOSE({1,2},(INDIRECT("'"&$B6&"'!$C$29:$C$45")),(INDIRECT("'"&$B6&"'!$A$29:$A$45"))),2,0),0)),(IFERROR(VLOOKUP(IFERROR(LOOKUP(2,1/((INDIRECT("'"&$B6&"'!$D$29:$D$45"))<>""),(INDIRECT("'"&$B6&"'!$D$29:$D$45"))),"NO DISPONIBLE"),CHOOSE({1,2},(INDIRECT("'"&$B6&"'!$D$29:$D$45")),(INDIRECT("'"&$B6&"'!$A$29:$A$45"))),2,0),0)),(IFERROR(VLOOKUP(IFERROR(LOOKUP(2,1/((INDIRECT("'"&$B6&"'!$C$29:$C$45"))<>""),(INDIRECT("'"&$B6&"'!$C$29:$C$45"))),"NO DISPONIBLE"),CHOOSE({1,2},(INDIRECT("'"&$B6&"'!$C$29:$C$45")),(INDIRECT("'"&$B6&"'!$A$29:$A$45"))),2,0),0)))} -> 0 | AA6: No aplica | AB6: {=IF((IFERROR(VLOOKUP(IFERROR(LOOKUP(2,1/((INDIRECT("'"&$B6&"'!$C$29:$C$45"))<>""),(INDIRECT("'"&$B6&"'!$C$29:$C$45"))),"NO DISPONIBLE"),CHOOSE({1,2},(INDIRECT("'"&$B6&"'!$C$29:$C$45")),(INDIRECT("'"&$B6&"'!$A$29:$A$45"))),2,0),0))>(IFERROR(VLOOKUP(IFERROR(LOOKUP(2,1/((INDIRECT("'"&$B6&"'!$D$29:$D$45"))<>""),(INDIRECT("'"&$B6&"'!$D$29:$D$45"))),"NO DISPONIBLE"),CHOOSE({1,2},(INDIRECT("'"&$B6&"'!$D$29:$D$45")),(INDIRECT("'"&$B6&"'!$A$29:$A$45"))),2,0),0)),IFERROR(LOOKUP(2,1/((INDIRECT("'"&$B6&"'!$C$29:$C$45"))<>""),(INDIRECT("'"&$B6&"'!$C$29:$C$45"))),"NO DISPONIBLE"),IFERROR(LOOKUP(2,1/((INDIRECT("'"&$B6&"'!$D$29:$D$45"))<>""),(INDIRECT("'"&$B6&"'!$D$29:$D$45"))),"NO DISPONIBLE"))} -> NO DISPONIBLE | AC6: ASEGURAMIENTO
A7: MJM-006 | B7: {=INDIRECT("'"&$B7&"'!$A$6")} -> MASA PATRÓN | C7: {=INDIRECT("'"&$B7&"'!$G$14")} -> COLMETRO | D7: {=INDIRECT("'"&$B7&"'!$G$15")} -> RECTANGULAR | E7: {=INDIRECT("'"&$B7&"'!$G$16")} -> MJM10-1 | F7: LABORATORIO 1 | G7: OPERATIVO | H7: {=INDIRECT("'"&$B7&"'!$G$11")} -> MASA | I7: {=INDIRECT("'"&$B7&"'!$C$11")} -> MEDIA | J7: {=INDIRECT("'"&$B7&"'!$G$21")} -> 10 kg | K7: {=INDIRECT("'"&$B7&"'!$G$22")} -> 10 kg | L7: {=INDIRECT("'"&$B7&"'!$G$23")} -> N/A | N7: {=INDIRECT("'"&$B7&"'!$G$22")} -> 10 kg | P7: {=IFERROR(LOOKUP(2,1/((INDIRECT("'"&$B7&"'!$G$29:$G$45"))<>""),(INDIRECT("'"&$B7&"'!$G$29:$G$45"))),"NO DISPONIBLE")} -> FUNCIONAL | Q7: N/A | R7: {=IF(IF(MAX((IFERROR((ROW(INDIRECT("'"&$B7&"'!$F$29:$F$45"))-ROW(INDIRECT("'"&$B7&"'!$F$29"))+1)/--(IF(INDIRECT("'"&$B7&"'!$F$29:$F$45")<>"",1,0)),0))-(IFERROR((ROW(INDIRECT("'"&$B7&"'!$F$29:$F$45"))-ROW(INDIRECT("'"&$B7&"'!$F$29"))+1)/--(FIND("VERIFICACIÓN: ", INDIRECT("'"&$B7&"'!$F$29:$F$45"))),0)))<>0,INDEX(INDIRECT("'"&$B7&"'!$A$29:$G$45"),MAX((IFERROR((ROW(INDIRECT("'"&$B7&"'!$F$29:$F$45"))-ROW(INDIRECT("'"&$B7&"'!$F$29"))+1)/--(IF(INDIRECT("'"&$B7&"'!$F$29:$F$45")<>"",1,0)),0))-(IFERROR((ROW(INDIRECT("'"&$B7&"'!$F$29:$F$45"))-ROW(INDIRECT("'"&$B7&"'!$F$29"))+1)/--(FIND("VERIFICACIÓN: ", INDIRECT("'"&$B7&"'!$F$29:$F$45"))),0))),1),0)>IF(MAX(IFERROR((_xlfn._xlws.FILTER((ROW(INDIRECT("'"&$B7&"'!$E$29:$E$45"))-ROW(INDIRECT("'"&$B7&"'!$E$29"))+1)/--(IF(INDIRECT("'"&$B7&"'!$E$29:$E$45")<>"",1,0)), NOT(ISNUMBER(MATCH((ROW(INDIRECT("'"&$B7&"'!$E$29:$E$45"))-ROW(INDIRECT("'"&$B7&"'!$E$29"))+1)/--(IF(INDIRECT("'"&$B7&"'!$E$29:$E$45")<>"",1,0)), (ROW(INDIRECT("'"&$B7&"'!$E$29:$E$45"))-ROW(INDIRECT("'"&$B7&"'!$E$29"))+1)/--(FIND("VERIFICACIÓN: ", INDIRECT("'"&$B7&"'!$E$29:$E$45"))), 0))))),0))<>0,INDEX(INDIRECT("'"&$B7&"'!$A$29:$G$45"),MAX((IFERROR((ROW(INDIRECT("'"&$B7&"'!$E$29:$E$45"))-ROW(INDIRECT("'"&$B7&"'!$E$29"))+1)/--(IF(INDIRECT("'"&$B7&"'!$E$29:$E$45")<>"",1,0)),0))-(IFERROR((ROW(INDIRECT("'"&$B7&"'!$E$29:$E$45"))-ROW(INDIRECT("'"&$B7&"'!$E$29"))+1)/--(FIND("VERIFICACIÓN: ", INDIRECT("'"&$B7&"'!$E$29:$E$45"))),0))),1),0),IF(MAX((IFERROR((ROW(INDIRECT("'"&$B7&"'!$F$29:$F$45"))-ROW(INDIRECT("'"&$B7&"'!$F$29"))+1)/--(IF(INDIRECT("'"&$B7&"'!$F$29:$F$45")<>"",1,0)),0))-(IFERROR((ROW(INDIRECT("'"&$B7&"'!$F$29:$F$45"))-ROW(INDIRECT("'"&$B7&"'!$F$29"))+1)/--(FIND("VERIFICACIÓN: ", INDIRECT("'"&$B7&"'!$F$29:$F$45"))),0)))<>0,INDEX(INDIRECT("'"&$B7&"'!$A$29:$G$45"),MAX((IFERROR((ROW(INDIRECT("'"&$B7&"'!$F$29:$F$45"))-ROW(INDIRECT("'"&$B7&"'!$F$29"))+1)/--(IF(INDIRECT("'"&$B7&"'!$F$29:$F$45")<>"",1,0)),0))-(IFERROR((ROW(INDIRECT("'"&$B7&"'!$F$29:$F$45"))-ROW(INDIRECT("'"&$B7&"'!$F$29"))+1)/--(FIND("VERIFICACIÓN: ", INDIRECT("'"&$B7&"'!$F$29:$F$45"))),0))),1),0),IF(MAX(IFERROR((_xlfn._xlws.FILTER((ROW(INDIRECT("'"&$B7&"'!$E$29:$E$45"))-ROW(INDIRECT("'"&$B7&"'!$E$29"))+1)/--(IF(INDIRECT("'"&$B7&"'!$E$29:$E$45")<>"",1,0)), NOT(ISNUMBER(MATCH((ROW(INDIRECT("'"&$B7&"'!$E$29:$E$45"))-ROW(INDIRECT("'"&$B7&"'!$E$29"))+1)/--(IF(INDIRECT("'"&$B7&"'!$E$29:$E$45")<>"",1,0)), (ROW(INDIRECT("'"&$B7&"'!$E$29:$E$45"))-ROW(INDIRECT("'"&$B7&"'!$E$29"))+1)/--(FIND("VERIFICACIÓN: ", INDIRECT("'"&$B7&"'!$E$29:$E$45"))), 0))))),0))<>0,INDEX(INDIRECT("'"&$B7&"'!$A$29:$G$45"),MAX((IFERROR((ROW(INDIRECT("'"&$B7&"'!$E$29:$E$45"))-ROW(INDIRECT("'"&$B7&"'!$E$29"))+1)/--(IF(INDIRECT("'"&$B7&"'!$E$29:$E$45")<>"",1,0)),0))-(IFERROR((ROW(INDIRECT("'"&$B7&"'!$E$29:$E$45"))-ROW(INDIRECT("'"&$B7&"'!$E$29"))+1)/--(FIND("VERIFICACIÓN: ", INDIRECT("'"&$B7&"'!$E$29:$E$45"))),0))),1),0))} -> 44875 | S7: No aplica | T7: {=IF(IF(MAX((IFERROR((ROW(INDIRECT("'"&$B7&"'!$F$29:$F$45"))-ROW(INDIRECT("'"&$B7&"'!$F$29"))+1)/--(IF(INDIRECT("'"&$B7&"'!$F$29:$F$45")<>"",1,0)),0))-(IFERROR((ROW(INDIRECT("'"&$B7&"'!$F$29:$F$45"))-ROW(INDIRECT("'"&$B7&"'!$F$29"))+1)/--(FIND("VERIFICACIÓN: ", INDIRECT("'"&$B7&"'!$F$29:$F$45"))),0)))<>0,INDEX(INDIRECT("'"&$B7&"'!$A$29:$G$45"),MAX((IFERROR((ROW(INDIRECT("'"&$B7&"'!$F$29:$F$45"))-ROW(INDIRECT("'"&$B7&"'!$F$29"))+1)/--(IF(INDIRECT("'"&$B7&"'!$F$29:$F$45")<>"",1,0)),0))-(IFERROR((ROW(INDIRECT("'"&$B7&"'!$F$29:$F$45"))-ROW(INDIRECT("'"&$B7&"'!$F$29"))+1)/--(FIND("VERIFICACIÓN: ", INDIRECT("'"&$B7&"'!$F$29:$F$45"))),0))),1),0)>IF(MAX(IFERROR((_xlfn._xlws.FILTER((ROW(INDIRECT("'"&$B7&"'!$E$29:$E$45"))-ROW(INDIRECT("'"&$B7&"'!$E$29"))+1)/--(IF(INDIRECT("'"&$B7&"'!$E$29:$E$45")<>"",1,0)), NOT(ISNUMBER(MATCH((ROW(INDIRECT("'"&$B7&"'!$E$29:$E$45"))-ROW(INDIRECT("'"&$B7&"'!$E$29"))+1)/--(IF(INDIRECT("'"&$B7&"'!$E$29:$E$45")<>"",1,0)), (ROW(INDIRECT("'"&$B7&"'!$E$29:$E$45"))-ROW(INDIRECT("'"&$B7&"'!$E$29"))+1)/--(FIND("VERIFICACIÓN: ", INDIRECT("'"&$B7&"'!$E$29:$E$45"))), 0))))),0))<>0,INDEX(INDIRECT("'"&$B7&"'!$A$29:$G$45"),MAX((IFERROR((ROW(INDIRECT("'"&$B7&"'!$E$29:$E$45"))-ROW(INDIRECT("'"&$B7&"'!$E$29"))+1)/--(IF(INDIRECT("'"&$B7&"'!$E$29:$E$45")<>"",1,0)),0))-(IFERROR((ROW(INDIRECT("'"&$B7&"'!$E$29:$E$45"))-ROW(INDIRECT("'"&$B7&"'!$E$29"))+1)/--(FIND("VERIFICACIÓN: ", INDIRECT("'"&$B7&"'!$E$29:$E$45"))),0))),1),0),IF(MAX((IFERROR((ROW(INDIRECT("'"&$B7&"'!$F$29:$F$45"))-ROW(INDIRECT("'"&$B7&"'!$F$29"))+1)/--(IF(INDIRECT("'"&$B7&"'!$F$29:$F$45")<>"",1,0)),0))-(IFERROR((ROW(INDIRECT("'"&$B7&"'!$F$29:$F$45"))-ROW(INDIRECT("'"&$B7&"'!$F$29"))+1)/--(FIND("VERIFICACIÓN: ", INDIRECT("'"&$B7&"'!$F$29:$F$45"))),0)))<>0,INDEX(INDIRECT("'"&$B7&"'!$A$29:$G$45"),MAX((IFERROR((ROW(INDIRECT("'"&$B7&"'!$F$29:$F$45"))-ROW(INDIRECT("'"&$B7&"'!$F$29"))+1)/--(IF(INDIRECT("'"&$B7&"'!$F$29:$F$45")<>"",1,0)),0))-(IFERROR((ROW(INDIRECT("'"&$B7&"'!$F$29:$F$45"))-ROW(INDIRECT("'"&$B7&"'!$F$29"))+1)/--(FIND("VERIFICACIÓN: ", INDIRECT("'"&$B7&"'!$F$29:$F$45"))),0))),6),"NO DISPONIBLE"),IF(MAX(IFERROR((_xlfn._xlws.FILTER((ROW(INDIRECT("'"&$B7&"'!$E$29:$E$45"))-ROW(INDIRECT("'"&$B7&"'!$E$29"))+1)/--(IF(INDIRECT("'"&$B7&"'!$E$29:$E$45")<>"",1,0)), NOT(ISNUMBER(MATCH((ROW(INDIRECT("'"&$B7&"'!$E$29:$E$45"))-ROW(INDIRECT("'"&$B7&"'!$E$29"))+1)/--(IF(INDIRECT("'"&$B7&"'!$E$29:$E$45")<>"",1,0)), (ROW(INDIRECT("'"&$B7&"'!$E$29:$E$45"))-ROW(INDIRECT("'"&$B7&"'!$E$29"))+1)/--(FIND("VERIFICACIÓN: ", INDIRECT("'"&$B7&"'!$E$29:$E$45"))), 0))))),0))<>0,INDEX(INDIRECT("'"&$B7&"'!$A$29:$G$45"),MAX((IFERROR((ROW(INDIRECT("'"&$B7&"'!$E$29:$E$45"))-ROW(INDIRECT("'"&$B7&"'!$E$29"))+1)/--(IF(INDIRECT("'"&$B7&"'!$E$29:$E$45")<>"",1,0)),0))-(IFERROR((ROW(INDIRECT("'"&$B7&"'!$E$29:$E$45"))-ROW(INDIRECT("'"&$B7&"'!$E$29"))+1)/--(FIND("VERIFICACIÓN: ", INDIRECT("'"&$B7&"'!$E$29:$E$45"))),0))),5),"NO DISPONIBLE"))} -> M221582 / COLETRO | U7: N/A | V7: {=IF((IFERROR(VLOOKUP(IFERROR(LOOKUP(2,1/((INDIRECT("'"&$B7&"'!$F$29:$F$45"))<>""),(INDIRECT("'"&$B7&"'!$F$29:$F$45"))),"NO DISPONIBLE"),CHOOSE({1,2},(INDIRECT("'"&$B7&"'!$F$29:$F$45")),(INDIRECT("'"&$B7&"'!$A$29:$A$45"))),2,0),0))>(IFERROR(VLOOKUP(IFERROR(LOOKUP(2,1/((INDIRECT("'"&$B7&"'!$E$29:$E$45"))<>""),(INDIRECT("'"&$B7&"'!$E$29:$E$45"))),"NO DISPONIBLE"),CHOOSE({1,2},(INDIRECT("'"&$B7&"'!$E$29:$E$45")),(INDIRECT("'"&$B7&"'!$A$29:$A$45"))),2,0),0)),(IFERROR(VLOOKUP(IFERROR(LOOKUP(2,1/((INDIRECT("'"&$B7&"'!$F$29:$F$45"))<>""),(INDIRECT("'"&$B7&"'!$F$29:$F$45"))),"NO DISPONIBLE"),CHOOSE({1,2},(INDIRECT("'"&$B7&"'!$F$29:$F$45")),(INDIRECT("'"&$B7&"'!$A$29:$A$45"))),2,0),0)),(IFERROR(VLOOKUP(IFERROR(LOOKUP(2,1/((INDIRECT("'"&$B7&"'!$E$29:$E$45"))<>""),(INDIRECT("'"&$B7&"'!$E$29:$E$45"))),"NO DISPONIBLE"),CHOOSE({1,2},(INDIRECT("'"&$B7&"'!$E$29:$E$45")),(INDIRECT("'"&$B7&"'!$A$29:$A$45"))),2,0),0)))} -> 44875 | W7: No aplica | X7: {=IF((IFERROR(VLOOKUP(IFERROR(LOOKUP(2,1/((INDIRECT("'"&$B7&"'!$E$29:$E$45"))<>""),(INDIRECT("'"&$B7&"'!$E$29:$E$45"))),"NO DISPONIBLE"),CHOOSE({1,2},(INDIRECT("'"&$B7&"'!$E$29:$E$45")),(INDIRECT("'"&$B7&"'!$A$29:$A$45"))),2,0),0))>(IFERROR(VLOOKUP(IFERROR(LOOKUP(2,1/((INDIRECT("'"&$B7&"'!$F$29:$F$45"))<>""),(INDIRECT("'"&$B7&"'!$F$29:$F$45"))),"NO DISPONIBLE"),CHOOSE({1,2},(INDIRECT("'"&$B7&"'!$F$29:$F$45")),(INDIRECT("'"&$B7&"'!$A$29:$A$45"))),2,0),0)),IFERROR(LOOKUP(2,1/((INDIRECT("'"&$B7&"'!$E$29:$E$45"))<>""),(INDIRECT("'"&$B7&"'!$E$29:$E$45"))),"NO DISPONIBLE"),IFERROR(LOOKUP(2,1/((INDIRECT("'"&$B7&"'!$F$29:$F$45"))<>""),(INDIRECT("'"&$B7&"'!$F$29:$F$45"))),"NO DISPONIBLE"))} -> M221582 / COLETRO | Y7: N/A | Z7: {=IF((IFERROR(VLOOKUP(IFERROR(LOOKUP(2,1/((INDIRECT("'"&$B7&"'!$D$29:$D$45"))<>""),(INDIRECT("'"&$B7&"'!$D$29:$D$45"))),"NO DISPONIBLE"),CHOOSE({1,2},(INDIRECT("'"&$B7&"'!$D$29:$D$45")),(INDIRECT("'"&$B7&"'!$A$29:$A$45"))),2,0),0))>(IFERROR(VLOOKUP(IFERROR(LOOKUP(2,1/((INDIRECT("'"&$B7&"'!$C$29:$C$45"))<>""),(INDIRECT("'"&$B7&"'!$C$29:$C$45"))),"NO DISPONIBLE"),CHOOSE({1,2},(INDIRECT("'"&$B7&"'!$C$29:$C$45")),(INDIRECT("'"&$B7&"'!$A$29:$A$45"))),2,0),0)),(IFERROR(VLOOKUP(IFERROR(LOOKUP(2,1/((INDIRECT("'"&$B7&"'!$D$29:$D$45"))<>""),(INDIRECT("'"&$B7&"'!$D$29:$D$45"))),"NO DISPONIBLE"),CHOOSE({1,2},(INDIRECT("'"&$B7&"'!$D$29:$D$45")),(INDIRECT("'"&$B7&"'!$A$29:$A$45"))),2,0),0)),(IFERROR(VLOOKUP(IFERROR(LOOKUP(2,1/((INDIRECT("'"&$B7&"'!$C$29:$C$45"))<>""),(INDIRECT("'"&$B7&"'!$C$29:$C$45"))),"NO DISPONIBLE"),CHOOSE({1,2},(INDIRECT("'"&$B7&"'!$C$29:$C$45")),(INDIRECT("'"&$B7&"'!$A$29:$A$45"))),2,0),0)))} -> 0 | AA7: No aplica | AB7: {=IF((IFERROR(VLOOKUP(IFERROR(LOOKUP(2,1/((INDIRECT("'"&$B7&"'!$C$29:$C$45"))<>""),(INDIRECT("'"&$B7&"'!$C$29:$C$45"))),"NO DISPONIBLE"),CHOOSE({1,2},(INDIRECT("'"&$B7&"'!$C$29:$C$45")),(INDIRECT("'"&$B7&"'!$A$29:$A$45"))),2,0),0))>(IFERROR(VLOOKUP(IFERROR(LOOKUP(2,1/((INDIRECT("'"&$B7&"'!$D$29:$D$45"))<>""),(INDIRECT("'"&$B7&"'!$D$29:$D$45"))),"NO DISPONIBLE"),CHOOSE({1,2},(INDIRECT("'"&$B7&"'!$D$29:$D$45")),(INDIRECT("'"&$B7&"'!$A$29:$A$45"))),2,0),0)),IFERROR(LOOKUP(2,1/((INDIRECT("'"&$B7&"'!$C$29:$C$45"))<>""),(INDIRECT("'"&$B7&"'!$C$29:$C$45"))),"NO DISPONIBLE"),IFERROR(LOOKUP(2,1/((INDIRECT("'"&$B7&"'!$D$29:$D$45"))<>""),(INDIRECT("'"&$B7&"'!$D$29:$D$45"))),"NO DISPONIBLE"))} -> NO DISPONIBLE | AC7: ASEGURAMIENTO
